INFO 2018-10-23 11:36:27,967 basehttp 124 "GET / HTTP/1.1" 200 1714
WARNING 2018-10-23 11:36:28,406 base 152 Not Found: /favicon.ico
WARNING 2018-10-23 11:36:28,428 basehttp 124 "GET /favicon.ico HTTP/1.1" 404 1973
INFO 2018-10-23 15:43:41,954 basehttp 124 "GET / HTTP/1.1" 200 1714
WARNING 2018-10-23 15:43:43,119 base 152 Not Found: /favicon.ico
WARNING 2018-10-23 15:43:43,123 basehttp 124 "GET /favicon.ico HTTP/1.1" 404 1973
INFO 2018-10-23 15:49:50,935 basehttp 124 "GET / HTTP/1.1" 200 1714
WARNING 2018-10-23 15:49:51,389 base 152 Not Found: /favicon.ico
WARNING 2018-10-23 15:49:51,398 basehttp 124 "GET /favicon.ico HTTP/1.1" 404 1979
WARNING 2018-10-23 20:41:28,339 base 152 Not Found: /
WARNING 2018-10-23 20:41:28,359 basehttp 124 "GET / HTTP/1.1" 404 2117
WARNING 2018-10-23 20:41:28,718 base 152 Not Found: /favicon.ico
WARNING 2018-10-23 20:41:28,719 basehttp 124 "GET /favicon.ico HTTP/1.1" 404 2168
WARNING 2018-10-23 20:42:06,262 base 152 Not Found: /
WARNING 2018-10-23 20:42:06,282 basehttp 124 "GET / HTTP/1.1" 404 2117
WARNING 2018-10-23 20:42:06,334 base 152 Not Found: /favicon.ico
WARNING 2018-10-23 20:42:06,341 basehttp 124 "GET /favicon.ico HTTP/1.1" 404 2168
WARNING 2018-10-23 20:42:46,704 base 152 Not Found: /
WARNING 2018-10-23 20:42:46,714 basehttp 124 "GET / HTTP/1.1" 404 2111
WARNING 2018-10-23 20:42:46,953 base 152 Not Found: /favicon.ico
WARNING 2018-10-23 20:42:46,980 basehttp 124 "GET /favicon.ico HTTP/1.1" 404 2162
WARNING 2018-10-23 20:43:56,561 base 152 Not Found: /usernames/123456/count/
WARNING 2018-10-23 20:43:56,585 basehttp 124 "GET /usernames/123456/count/ HTTP/1.1" 404 2204
WARNING 2018-10-23 20:44:19,259 base 152 Not Found: /mobiles/17605272633/count/
WARNING 2018-10-23 20:44:19,263 basehttp 124 "GET /mobiles/17605272633/count/ HTTP/1.1" 404 2213
WARNING 2018-10-23 20:44:20,146 base 152 Not Found: /mobiles/17605272633/count/
WARNING 2018-10-23 20:44:20,151 basehttp 124 "GET /mobiles/17605272633/count/ HTTP/1.1" 404 2213
INFO 2018-10-23 20:44:20,275 basehttp 124 "GET /sms_code/17605272633/ HTTP/1.1" 200 16
WARNING 2018-10-23 21:25:08,948 base 152 Not Found: /usernames/00000000/count/
WARNING 2018-10-23 21:25:08,956 basehttp 124 "GET /usernames/00000000/count/ HTTP/1.1" 404 2210
WARNING 2018-10-23 21:25:17,301 base 152 Not Found: /mobiles/17605272633/count/
WARNING 2018-10-23 21:25:17,307 basehttp 124 "GET /mobiles/17605272633/count/ HTTP/1.1" 404 2213
WARNING 2018-10-23 21:25:17,989 base 152 Not Found: /mobiles/17605272633/count/
WARNING 2018-10-23 21:25:17,994 basehttp 124 "GET /mobiles/17605272633/count/ HTTP/1.1" 404 2213
INFO 2018-10-23 21:25:18,224 basehttp 124 "GET /sms_code/17605272633/ HTTP/1.1" 200 16
WARNING 2018-10-23 21:26:55,501 base 152 Not Found: /mobiles/17605272633/count/
WARNING 2018-10-23 21:26:55,525 basehttp 124 "GET /mobiles/17605272633/count/ HTTP/1.1" 404 2213
INFO 2018-10-23 21:26:55,518 basehttp 124 "GET /sms_code/17605272633/ HTTP/1.1" 200 16
WARNING 2018-10-23 21:27:58,201 base 152 Not Found: /usernames/12345678/count/
WARNING 2018-10-23 21:27:58,208 basehttp 124 "GET /usernames/12345678/count/ HTTP/1.1" 404 2210
WARNING 2018-10-23 21:28:07,968 base 152 Not Found: /mobiles/17605272633/count/
WARNING 2018-10-23 21:28:07,972 basehttp 124 "GET /mobiles/17605272633/count/ HTTP/1.1" 404 2213
WARNING 2018-10-23 21:28:08,112 base 152 Not Found: /mobiles/17605272633/count/
WARNING 2018-10-23 21:28:08,116 basehttp 124 "GET /mobiles/17605272633/count/ HTTP/1.1" 404 2213
INFO 2018-10-23 21:28:08,292 basehttp 124 "GET /sms_code/17605272633/ HTTP/1.1" 200 16
WARNING 2018-10-23 21:28:46,127 base 152 Not Found: /usernames/12345678/count/
WARNING 2018-10-23 21:28:46,131 basehttp 124 "GET /usernames/12345678/count/ HTTP/1.1" 404 2210
WARNING 2018-10-23 21:28:55,251 base 152 Not Found: /mobiles/17605272633/count/
WARNING 2018-10-23 21:28:55,256 basehttp 124 "GET /mobiles/17605272633/count/ HTTP/1.1" 404 2213
WARNING 2018-10-23 21:28:55,729 base 152 Not Found: /mobiles/17605272633/count/
WARNING 2018-10-23 21:28:55,733 basehttp 124 "GET /sms_code/17605272633/ HTTP/1.1" 400 28
WARNING 2018-10-23 21:28:55,745 basehttp 124 "GET /mobiles/17605272633/count/ HTTP/1.1" 404 2213
WARNING 2018-10-23 21:29:00,536 base 152 Not Found: /mobiles/17605272633/count/
WARNING 2018-10-23 21:29:00,542 basehttp 124 "GET /mobiles/17605272633/count/ HTTP/1.1" 404 2213
WARNING 2018-10-23 21:29:00,546 basehttp 124 "GET /sms_code/17605272633/ HTTP/1.1" 400 28
WARNING 2018-10-23 21:29:49,869 base 152 Not Found: /usernames/12345678/count/
WARNING 2018-10-23 21:29:49,873 basehttp 124 "GET /usernames/12345678/count/ HTTP/1.1" 404 2210
WARNING 2018-10-23 21:29:59,855 base 152 Not Found: /mobiles/17605272633/count/
WARNING 2018-10-23 21:29:59,859 basehttp 124 "GET /mobiles/17605272633/count/ HTTP/1.1" 404 2213
WARNING 2018-10-23 21:29:59,971 base 152 Not Found: /mobiles/17605272633/count/
WARNING 2018-10-23 21:29:59,979 basehttp 124 "GET /mobiles/17605272633/count/ HTTP/1.1" 404 2213
INFO 2018-10-23 21:30:00,768 basehttp 124 "GET /sms_code/17605272633/ HTTP/1.1" 200 16
WARNING 2018-10-23 21:30:44,678 base 152 Not Found: /usernames/00000000/count/
WARNING 2018-10-23 21:30:44,685 basehttp 124 "GET /usernames/00000000/count/ HTTP/1.1" 404 2210
WARNING 2018-10-23 21:30:55,017 base 152 Not Found: /mobiles/17605272633/count/
WARNING 2018-10-23 21:30:55,021 basehttp 124 "GET /mobiles/17605272633/count/ HTTP/1.1" 404 2213
WARNING 2018-10-23 21:30:55,128 base 152 Not Found: /mobiles/17605272633/count/
WARNING 2018-10-23 21:30:55,132 basehttp 124 "GET /mobiles/17605272633/count/ HTTP/1.1" 404 2213
WARNING 2018-10-23 21:30:55,141 basehttp 124 "GET /sms_code/17605272633/ HTTP/1.1" 400 28
WARNING 2018-10-23 21:30:58,340 basehttp 124 "GET /sms_code/17605272633/ HTTP/1.1" 400 28
WARNING 2018-10-23 21:30:58,344 base 152 Not Found: /mobiles/17605272633/count/
WARNING 2018-10-23 21:30:58,347 basehttp 124 "GET /mobiles/17605272633/count/ HTTP/1.1" 404 2213
WARNING 2018-10-23 21:37:34,978 base 152 Not Found: /usernames/qqqqqqq/count/
WARNING 2018-10-23 21:37:34,984 basehttp 124 "GET /usernames/qqqqqqq/count/ HTTP/1.1" 404 2207
WARNING 2018-10-23 21:37:44,866 base 152 Not Found: /mobiles/17605272633/count/
WARNING 2018-10-23 21:37:44,871 basehttp 124 "GET /mobiles/17605272633/count/ HTTP/1.1" 404 2213
WARNING 2018-10-23 21:37:45,022 base 152 Not Found: /mobiles/17605272633/count/
INFO 2018-10-23 21:37:45,025 basehttp 124 "GET /sms_code/17605272633/ HTTP/1.1" 200 16
WARNING 2018-10-23 21:37:45,028 basehttp 124 "GET /mobiles/17605272633/count/ HTTP/1.1" 404 2213
WARNING 2018-10-23 21:42:44,815 base 152 Not Found: /usernames/00000000/count/
WARNING 2018-10-23 21:42:44,819 basehttp 124 "GET /usernames/00000000/count/ HTTP/1.1" 404 2210
WARNING 2018-10-23 21:43:01,032 base 152 Not Found: /mobiles/17605272633/count/
WARNING 2018-10-23 21:43:01,035 basehttp 124 "GET /mobiles/17605272633/count/ HTTP/1.1" 404 2213
WARNING 2018-10-23 21:43:01,153 base 152 Not Found: /mobiles/17605272633/count/
WARNING 2018-10-23 21:43:01,156 basehttp 124 "GET /mobiles/17605272633/count/ HTTP/1.1" 404 2213
INFO 2018-10-23 21:43:01,904 basehttp 124 "GET /sms_code/17605272633/ HTTP/1.1" 200 16
WARNING 2018-10-23 21:44:06,159 base 152 Not Found: /usernames/00000000/count/
WARNING 2018-10-23 21:44:06,166 basehttp 124 "GET /usernames/00000000/count/ HTTP/1.1" 404 2210
WARNING 2018-10-23 21:44:14,780 base 152 Not Found: /mobiles/17605272633/count/
WARNING 2018-10-23 21:44:14,786 basehttp 124 "GET /mobiles/17605272633/count/ HTTP/1.1" 404 2213
WARNING 2018-10-23 21:44:14,925 base 152 Not Found: /mobiles/17605272633/count/
WARNING 2018-10-23 21:44:14,934 basehttp 124 "GET /mobiles/17605272633/count/ HTTP/1.1" 404 2213
INFO 2018-10-23 21:44:15,020 basehttp 124 "GET /sms_code/17605272633/ HTTP/1.1" 200 16
WARNING 2018-10-23 21:44:57,035 base 152 Not Found: /usernames/00000000/count/
WARNING 2018-10-23 21:44:57,040 basehttp 124 "GET /usernames/00000000/count/ HTTP/1.1" 404 2210
WARNING 2018-10-23 21:45:05,178 base 152 Not Found: /mobiles/17605272633/count/
WARNING 2018-10-23 21:45:05,185 basehttp 124 "GET /mobiles/17605272633/count/ HTTP/1.1" 404 2213
WARNING 2018-10-23 21:45:05,230 base 152 Not Found: /mobiles/17605272633/count/
WARNING 2018-10-23 21:45:05,242 basehttp 124 "GET /mobiles/17605272633/count/ HTTP/1.1" 404 2213
INFO 2018-10-23 21:45:05,340 basehttp 124 "GET /sms_code/17605272633/ HTTP/1.1" 200 16
WARNING 2018-10-23 21:50:17,574 base 152 Not Found: /usernames/00000000/count/
WARNING 2018-10-23 21:50:17,579 basehttp 124 "GET /usernames/00000000/count/ HTTP/1.1" 404 2210
WARNING 2018-10-23 21:50:25,641 base 152 Not Found: /mobiles/17605272633/count/
WARNING 2018-10-23 21:50:25,648 basehttp 124 "GET /mobiles/17605272633/count/ HTTP/1.1" 404 2213
WARNING 2018-10-23 21:50:25,774 base 152 Not Found: /mobiles/17605272633/count/
WARNING 2018-10-23 21:50:25,782 basehttp 124 "GET /mobiles/17605272633/count/ HTTP/1.1" 404 2213
INFO 2018-10-23 21:50:25,877 basehttp 124 "GET /sms_code/17605272633/ HTTP/1.1" 200 16
WARNING 2018-10-23 23:53:01,991 base 152 Not Found: /usernames/00000000/count/
WARNING 2018-10-23 23:53:01,997 basehttp 124 "GET /usernames/00000000/count/ HTTP/1.1" 404 2210
WARNING 2018-10-23 23:53:17,297 base 152 Not Found: /mobiles/17605272633/count/
WARNING 2018-10-23 23:53:17,302 basehttp 124 "GET /mobiles/17605272633/count/ HTTP/1.1" 404 2213
WARNING 2018-10-23 23:53:17,418 base 152 Not Found: /mobiles/17605272633/count/
WARNING 2018-10-23 23:53:17,429 basehttp 124 "GET /mobiles/17605272633/count/ HTTP/1.1" 404 2213
INFO 2018-10-23 23:53:17,804 basehttp 124 "GET /sms_code/17605272633/ HTTP/1.1" 200 16
WARNING 2018-10-24 00:02:47,019 base 152 Not Found: /usernames/00000000/count/
WARNING 2018-10-24 00:02:47,026 basehttp 124 "GET /usernames/00000000/count/ HTTP/1.1" 404 2210
WARNING 2018-10-24 00:02:56,311 base 152 Not Found: /mobiles/17605272633/count/
WARNING 2018-10-24 00:02:56,315 basehttp 124 "GET /mobiles/17605272633/count/ HTTP/1.1" 404 2213
WARNING 2018-10-24 00:02:56,462 base 152 Not Found: /mobiles/17605272633/count/
WARNING 2018-10-24 00:02:56,488 basehttp 124 "GET /mobiles/17605272633/count/ HTTP/1.1" 404 2213
INFO 2018-10-24 00:02:56,804 basehttp 124 "GET /sms_code/17605272633/ HTTP/1.1" 200 16
WARNING 2018-10-24 00:45:02,615 base 152 Not Found: /mobiles/17605272633/count/
WARNING 2018-10-24 00:45:02,628 basehttp 124 "GET /mobiles/17605272633/count/ HTTP/1.1" 404 2213
WARNING 2018-10-24 00:45:07,448 base 152 Not Found: /mobiles/17605272633/count/
WARNING 2018-10-24 00:45:07,454 basehttp 124 "GET /mobiles/17605272633/count/ HTTP/1.1" 404 2213
INFO 2018-10-24 00:45:07,986 basehttp 124 "GET /sms_code/17605272633/ HTTP/1.1" 200 16
WARNING 2018-10-24 00:49:08,407 base 152 Not Found: /mobiles/17605272633/count/
WARNING 2018-10-24 00:49:08,423 basehttp 124 "GET /mobiles/17605272633/count/ HTTP/1.1" 404 2213
INFO 2018-10-24 00:49:08,790 basehttp 124 "GET /sms_code/17605272633/ HTTP/1.1" 200 16
WARNING 2018-10-24 00:50:14,947 base 152 Not Found: /mobiles/17605272633/count/
WARNING 2018-10-24 00:50:14,959 basehttp 124 "GET /mobiles/17605272633/count/ HTTP/1.1" 404 2213
WARNING 2018-10-24 00:50:15,001 base 152 Not Found: /mobiles/17605272633/count/
WARNING 2018-10-24 00:50:15,007 basehttp 124 "GET /mobiles/17605272633/count/ HTTP/1.1" 404 2213
INFO 2018-10-24 00:50:15,311 basehttp 124 "GET /sms_code/17605272633/ HTTP/1.1" 200 16
WARNING 2018-10-24 00:51:12,354 base 152 Not Found: /mobiles/17605272633/count/
WARNING 2018-10-24 00:51:12,370 basehttp 124 "GET /mobiles/17605272633/count/ HTTP/1.1" 404 2213
WARNING 2018-10-24 00:51:12,393 base 152 Not Found: /mobiles/17605272633/count/
WARNING 2018-10-24 00:51:12,409 basehttp 124 "GET /mobiles/17605272633/count/ HTTP/1.1" 404 2213
INFO 2018-10-24 00:51:12,658 basehttp 124 "GET /sms_code/17605272633/ HTTP/1.1" 200 16
WARNING 2018-10-24 00:58:26,102 base 152 Not Found: /mobiles/17605272633/count/
WARNING 2018-10-24 00:58:26,113 basehttp 124 "GET /mobiles/17605272633/count/ HTTP/1.1" 404 2213
INFO 2018-10-24 00:58:26,430 basehttp 124 "GET /sms_code/17605272633/ HTTP/1.1" 200 16
WARNING 2018-10-24 01:00:32,007 base 152 Not Found: /mobiles/17605272633/count/
WARNING 2018-10-24 01:00:32,027 basehttp 124 "GET /mobiles/17605272633/count/ HTTP/1.1" 404 2213
WARNING 2018-10-24 01:00:32,100 base 152 Not Found: /mobiles/17605272633/count/
WARNING 2018-10-24 01:00:32,108 basehttp 124 "GET /mobiles/17605272633/count/ HTTP/1.1" 404 2213
INFO 2018-10-24 01:00:32,495 basehttp 124 "GET /sms_code/17605272633/ HTTP/1.1" 200 16
WARNING 2018-10-24 01:03:33,134 base 152 Not Found: /mobiles/17605272633/count/
WARNING 2018-10-24 01:03:33,163 basehttp 124 "GET /mobiles/17605272633/count/ HTTP/1.1" 404 2213
WARNING 2018-10-24 01:03:33,273 base 152 Not Found: /mobiles/17605272633/count/
WARNING 2018-10-24 01:03:33,285 basehttp 124 "GET /mobiles/17605272633/count/ HTTP/1.1" 404 2213
INFO 2018-10-24 01:03:33,822 basehttp 124 "GET /sms_code/17605272633/ HTTP/1.1" 200 16
ERROR 2018-10-24 11:31:49,951 exception 135 Internal Server Error: /usernames/00000000/count/
Traceback (most recent call last):
  File "/home/python/.virtualenvs/py3_django_1.11/lib/python3.5/site-packages/django/core/handlers/exception.py", line 41, in inner
    response = get_response(request)
  File "/home/python/.virtualenvs/py3_django_1.11/lib/python3.5/site-packages/django/core/handlers/base.py", line 187, in _get_response
    response = self.process_exception_by_middleware(e, request)
  File "/home/python/.virtualenvs/py3_django_1.11/lib/python3.5/site-packages/django/core/handlers/base.py", line 185, in _get_response
    response = wrapped_callback(request, *callback_args, **callback_kwargs)
  File "/home/python/.virtualenvs/py3_django_1.11/lib/python3.5/site-packages/django/views/decorators/csrf.py", line 58, in wrapped_view
    return view_func(*args, **kwargs)
  File "/home/python/.virtualenvs/py3_django_1.11/lib/python3.5/site-packages/django/views/generic/base.py", line 68, in view
    return self.dispatch(request, *args, **kwargs)
  File "/home/python/.virtualenvs/py3_django_1.11/lib/python3.5/site-packages/rest_framework/views.py", line 483, in dispatch
    response = self.handle_exception(exc)
  File "/home/python/.virtualenvs/py3_django_1.11/lib/python3.5/site-packages/rest_framework/views.py", line 443, in handle_exception
    self.raise_uncaught_exception(exc)
  File "/home/python/.virtualenvs/py3_django_1.11/lib/python3.5/site-packages/rest_framework/views.py", line 480, in dispatch
    response = handler(request, *args, **kwargs)
  File "/home/python/Desktop/meiduo/ManyBeautifulMall/ManyBeautiful/ManyBeautifulMall/apps/users/views.py", line 24, in get
    count = User.object.filter(username=username).count()
AttributeError: type object 'User' has no attribute 'object'
ERROR 2018-10-24 11:31:50,207 basehttp 124 "GET /usernames/00000000/count/ HTTP/1.1" 500 18356
INFO 2018-10-24 11:31:59,260 basehttp 124 "GET /mobiles/17605272633/count/ HTTP/1.1" 200 34
INFO 2018-10-24 11:31:59,264 basehttp 124 "GET /sms_code/17605272633/ HTTP/1.1" 200 16
INFO 2018-10-24 11:31:59,276 basehttp 124 "GET /mobiles/17605272633/count/ HTTP/1.1" 200 34
ERROR 2018-10-24 11:32:20,004 exception 135 Internal Server Error: /usernames/00000000/count/
Traceback (most recent call last):
  File "/home/python/.virtualenvs/py3_django_1.11/lib/python3.5/site-packages/django/core/handlers/exception.py", line 41, in inner
    response = get_response(request)
  File "/home/python/.virtualenvs/py3_django_1.11/lib/python3.5/site-packages/django/core/handlers/base.py", line 187, in _get_response
    response = self.process_exception_by_middleware(e, request)
  File "/home/python/.virtualenvs/py3_django_1.11/lib/python3.5/site-packages/django/core/handlers/base.py", line 185, in _get_response
    response = wrapped_callback(request, *callback_args, **callback_kwargs)
  File "/home/python/.virtualenvs/py3_django_1.11/lib/python3.5/site-packages/django/views/decorators/csrf.py", line 58, in wrapped_view
    return view_func(*args, **kwargs)
  File "/home/python/.virtualenvs/py3_django_1.11/lib/python3.5/site-packages/django/views/generic/base.py", line 68, in view
    return self.dispatch(request, *args, **kwargs)
  File "/home/python/.virtualenvs/py3_django_1.11/lib/python3.5/site-packages/rest_framework/views.py", line 483, in dispatch
    response = self.handle_exception(exc)
  File "/home/python/.virtualenvs/py3_django_1.11/lib/python3.5/site-packages/rest_framework/views.py", line 443, in handle_exception
    self.raise_uncaught_exception(exc)
  File "/home/python/.virtualenvs/py3_django_1.11/lib/python3.5/site-packages/rest_framework/views.py", line 480, in dispatch
    response = handler(request, *args, **kwargs)
  File "/home/python/Desktop/meiduo/ManyBeautifulMall/ManyBeautiful/ManyBeautifulMall/apps/users/views.py", line 24, in get
    count = User.object.filter(username=username).count()
AttributeError: type object 'User' has no attribute 'object'
INFO 2018-10-24 11:32:20,027 basehttp 124 "GET /mobiles/17605272633/count/ HTTP/1.1" 200 34
INFO 2018-10-24 11:32:20,036 basehttp 124 "OPTIONS /users/ HTTP/1.1" 200 0
ERROR 2018-10-24 11:32:20,044 basehttp 124 "GET /usernames/00000000/count/ HTTP/1.1" 500 18356
ERROR 2018-10-24 11:32:21,185 exception 135 Internal Server Error: /usernames/00000000/count/
Traceback (most recent call last):
  File "/home/python/.virtualenvs/py3_django_1.11/lib/python3.5/site-packages/django/core/handlers/exception.py", line 41, in inner
    response = get_response(request)
  File "/home/python/.virtualenvs/py3_django_1.11/lib/python3.5/site-packages/django/core/handlers/base.py", line 187, in _get_response
    response = self.process_exception_by_middleware(e, request)
  File "/home/python/.virtualenvs/py3_django_1.11/lib/python3.5/site-packages/django/core/handlers/base.py", line 185, in _get_response
    response = wrapped_callback(request, *callback_args, **callback_kwargs)
  File "/home/python/.virtualenvs/py3_django_1.11/lib/python3.5/site-packages/django/views/decorators/csrf.py", line 58, in wrapped_view
    return view_func(*args, **kwargs)
  File "/home/python/.virtualenvs/py3_django_1.11/lib/python3.5/site-packages/django/views/generic/base.py", line 68, in view
    return self.dispatch(request, *args, **kwargs)
  File "/home/python/.virtualenvs/py3_django_1.11/lib/python3.5/site-packages/rest_framework/views.py", line 483, in dispatch
    response = self.handle_exception(exc)
  File "/home/python/.virtualenvs/py3_django_1.11/lib/python3.5/site-packages/rest_framework/views.py", line 443, in handle_exception
    self.raise_uncaught_exception(exc)
  File "/home/python/.virtualenvs/py3_django_1.11/lib/python3.5/site-packages/rest_framework/views.py", line 480, in dispatch
    response = handler(request, *args, **kwargs)
  File "/home/python/Desktop/meiduo/ManyBeautifulMall/ManyBeautiful/ManyBeautifulMall/apps/users/views.py", line 24, in get
    count = User.object.filter(username=username).count()
AttributeError: type object 'User' has no attribute 'object'
INFO 2018-10-24 11:32:21,198 basehttp 124 "OPTIONS /users/ HTTP/1.1" 200 0
ERROR 2018-10-24 11:32:21,228 basehttp 124 "GET /usernames/00000000/count/ HTTP/1.1" 500 18356
INFO 2018-10-24 11:32:21,311 basehttp 124 "GET /mobiles/17605272633/count/ HTTP/1.1" 200 34
ERROR 2018-10-24 11:32:24,368 exception 135 Internal Server Error: /usernames/00000000/count/
Traceback (most recent call last):
  File "/home/python/.virtualenvs/py3_django_1.11/lib/python3.5/site-packages/django/core/handlers/exception.py", line 41, in inner
    response = get_response(request)
  File "/home/python/.virtualenvs/py3_django_1.11/lib/python3.5/site-packages/django/core/handlers/base.py", line 187, in _get_response
    response = self.process_exception_by_middleware(e, request)
  File "/home/python/.virtualenvs/py3_django_1.11/lib/python3.5/site-packages/django/core/handlers/base.py", line 185, in _get_response
    response = wrapped_callback(request, *callback_args, **callback_kwargs)
  File "/home/python/.virtualenvs/py3_django_1.11/lib/python3.5/site-packages/django/views/decorators/csrf.py", line 58, in wrapped_view
    return view_func(*args, **kwargs)
  File "/home/python/.virtualenvs/py3_django_1.11/lib/python3.5/site-packages/django/views/generic/base.py", line 68, in view
    return self.dispatch(request, *args, **kwargs)
  File "/home/python/.virtualenvs/py3_django_1.11/lib/python3.5/site-packages/rest_framework/views.py", line 483, in dispatch
    response = self.handle_exception(exc)
  File "/home/python/.virtualenvs/py3_django_1.11/lib/python3.5/site-packages/rest_framework/views.py", line 443, in handle_exception
    self.raise_uncaught_exception(exc)
  File "/home/python/.virtualenvs/py3_django_1.11/lib/python3.5/site-packages/rest_framework/views.py", line 480, in dispatch
    response = handler(request, *args, **kwargs)
  File "/home/python/Desktop/meiduo/ManyBeautifulMall/ManyBeautiful/ManyBeautifulMall/apps/users/views.py", line 24, in get
    count = User.object.filter(username=username).count()
AttributeError: type object 'User' has no attribute 'object'
INFO 2018-10-24 11:32:24,384 basehttp 124 "OPTIONS /users/ HTTP/1.1" 200 0
INFO 2018-10-24 11:32:24,390 basehttp 124 "GET /mobiles/17605272633/count/ HTTP/1.1" 200 34
ERROR 2018-10-24 11:32:24,411 basehttp 124 "GET /usernames/00000000/count/ HTTP/1.1" 500 18356
ERROR 2018-10-24 11:32:24,740 exception 135 Internal Server Error: /usernames/00000000/count/
Traceback (most recent call last):
  File "/home/python/.virtualenvs/py3_django_1.11/lib/python3.5/site-packages/django/core/handlers/exception.py", line 41, in inner
    response = get_response(request)
  File "/home/python/.virtualenvs/py3_django_1.11/lib/python3.5/site-packages/django/core/handlers/base.py", line 187, in _get_response
    response = self.process_exception_by_middleware(e, request)
  File "/home/python/.virtualenvs/py3_django_1.11/lib/python3.5/site-packages/django/core/handlers/base.py", line 185, in _get_response
    response = wrapped_callback(request, *callback_args, **callback_kwargs)
  File "/home/python/.virtualenvs/py3_django_1.11/lib/python3.5/site-packages/django/views/decorators/csrf.py", line 58, in wrapped_view
    return view_func(*args, **kwargs)
  File "/home/python/.virtualenvs/py3_django_1.11/lib/python3.5/site-packages/django/views/generic/base.py", line 68, in view
    return self.dispatch(request, *args, **kwargs)
  File "/home/python/.virtualenvs/py3_django_1.11/lib/python3.5/site-packages/rest_framework/views.py", line 483, in dispatch
    response = self.handle_exception(exc)
  File "/home/python/.virtualenvs/py3_django_1.11/lib/python3.5/site-packages/rest_framework/views.py", line 443, in handle_exception
    self.raise_uncaught_exception(exc)
  File "/home/python/.virtualenvs/py3_django_1.11/lib/python3.5/site-packages/rest_framework/views.py", line 480, in dispatch
    response = handler(request, *args, **kwargs)
  File "/home/python/Desktop/meiduo/ManyBeautifulMall/ManyBeautiful/ManyBeautifulMall/apps/users/views.py", line 24, in get
    count = User.object.filter(username=username).count()
AttributeError: type object 'User' has no attribute 'object'
INFO 2018-10-24 11:32:24,753 basehttp 124 "OPTIONS /users/ HTTP/1.1" 200 0
INFO 2018-10-24 11:32:24,764 basehttp 124 "GET /mobiles/17605272633/count/ HTTP/1.1" 200 34
ERROR 2018-10-24 11:32:24,795 basehttp 124 "GET /usernames/00000000/count/ HTTP/1.1" 500 18356
ERROR 2018-10-24 11:32:24,897 exception 135 Internal Server Error: /usernames/00000000/count/
Traceback (most recent call last):
  File "/home/python/.virtualenvs/py3_django_1.11/lib/python3.5/site-packages/django/core/handlers/exception.py", line 41, in inner
    response = get_response(request)
  File "/home/python/.virtualenvs/py3_django_1.11/lib/python3.5/site-packages/django/core/handlers/base.py", line 187, in _get_response
    response = self.process_exception_by_middleware(e, request)
  File "/home/python/.virtualenvs/py3_django_1.11/lib/python3.5/site-packages/django/core/handlers/base.py", line 185, in _get_response
    response = wrapped_callback(request, *callback_args, **callback_kwargs)
  File "/home/python/.virtualenvs/py3_django_1.11/lib/python3.5/site-packages/django/views/decorators/csrf.py", line 58, in wrapped_view
    return view_func(*args, **kwargs)
  File "/home/python/.virtualenvs/py3_django_1.11/lib/python3.5/site-packages/django/views/generic/base.py", line 68, in view
    return self.dispatch(request, *args, **kwargs)
  File "/home/python/.virtualenvs/py3_django_1.11/lib/python3.5/site-packages/rest_framework/views.py", line 483, in dispatch
    response = self.handle_exception(exc)
  File "/home/python/.virtualenvs/py3_django_1.11/lib/python3.5/site-packages/rest_framework/views.py", line 443, in handle_exception
    self.raise_uncaught_exception(exc)
  File "/home/python/.virtualenvs/py3_django_1.11/lib/python3.5/site-packages/rest_framework/views.py", line 480, in dispatch
    response = handler(request, *args, **kwargs)
  File "/home/python/Desktop/meiduo/ManyBeautifulMall/ManyBeautiful/ManyBeautifulMall/apps/users/views.py", line 24, in get
    count = User.object.filter(username=username).count()
AttributeError: type object 'User' has no attribute 'object'
INFO 2018-10-24 11:32:24,910 basehttp 124 "OPTIONS /users/ HTTP/1.1" 200 0
INFO 2018-10-24 11:32:24,927 basehttp 124 "GET /mobiles/17605272633/count/ HTTP/1.1" 200 34
ERROR 2018-10-24 11:32:24,959 basehttp 124 "GET /usernames/00000000/count/ HTTP/1.1" 500 18356
ERROR 2018-10-24 11:32:25,040 exception 135 Internal Server Error: /usernames/00000000/count/
Traceback (most recent call last):
  File "/home/python/.virtualenvs/py3_django_1.11/lib/python3.5/site-packages/django/core/handlers/exception.py", line 41, in inner
    response = get_response(request)
  File "/home/python/.virtualenvs/py3_django_1.11/lib/python3.5/site-packages/django/core/handlers/base.py", line 187, in _get_response
    response = self.process_exception_by_middleware(e, request)
  File "/home/python/.virtualenvs/py3_django_1.11/lib/python3.5/site-packages/django/core/handlers/base.py", line 185, in _get_response
    response = wrapped_callback(request, *callback_args, **callback_kwargs)
  File "/home/python/.virtualenvs/py3_django_1.11/lib/python3.5/site-packages/django/views/decorators/csrf.py", line 58, in wrapped_view
    return view_func(*args, **kwargs)
  File "/home/python/.virtualenvs/py3_django_1.11/lib/python3.5/site-packages/django/views/generic/base.py", line 68, in view
    return self.dispatch(request, *args, **kwargs)
  File "/home/python/.virtualenvs/py3_django_1.11/lib/python3.5/site-packages/rest_framework/views.py", line 483, in dispatch
    response = self.handle_exception(exc)
  File "/home/python/.virtualenvs/py3_django_1.11/lib/python3.5/site-packages/rest_framework/views.py", line 443, in handle_exception
    self.raise_uncaught_exception(exc)
  File "/home/python/.virtualenvs/py3_django_1.11/lib/python3.5/site-packages/rest_framework/views.py", line 480, in dispatch
    response = handler(request, *args, **kwargs)
  File "/home/python/Desktop/meiduo/ManyBeautifulMall/ManyBeautiful/ManyBeautifulMall/apps/users/views.py", line 24, in get
    count = User.object.filter(username=username).count()
AttributeError: type object 'User' has no attribute 'object'
INFO 2018-10-24 11:32:25,058 basehttp 124 "OPTIONS /users/ HTTP/1.1" 200 0
INFO 2018-10-24 11:32:25,090 basehttp 124 "GET /mobiles/17605272633/count/ HTTP/1.1" 200 34
ERROR 2018-10-24 11:32:25,094 basehttp 124 "GET /usernames/00000000/count/ HTTP/1.1" 500 18356
ERROR 2018-10-24 11:32:25,189 exception 135 Internal Server Error: /usernames/00000000/count/
Traceback (most recent call last):
  File "/home/python/.virtualenvs/py3_django_1.11/lib/python3.5/site-packages/django/core/handlers/exception.py", line 41, in inner
    response = get_response(request)
  File "/home/python/.virtualenvs/py3_django_1.11/lib/python3.5/site-packages/django/core/handlers/base.py", line 187, in _get_response
    response = self.process_exception_by_middleware(e, request)
  File "/home/python/.virtualenvs/py3_django_1.11/lib/python3.5/site-packages/django/core/handlers/base.py", line 185, in _get_response
    response = wrapped_callback(request, *callback_args, **callback_kwargs)
  File "/home/python/.virtualenvs/py3_django_1.11/lib/python3.5/site-packages/django/views/decorators/csrf.py", line 58, in wrapped_view
    return view_func(*args, **kwargs)
  File "/home/python/.virtualenvs/py3_django_1.11/lib/python3.5/site-packages/django/views/generic/base.py", line 68, in view
    return self.dispatch(request, *args, **kwargs)
  File "/home/python/.virtualenvs/py3_django_1.11/lib/python3.5/site-packages/rest_framework/views.py", line 483, in dispatch
    response = self.handle_exception(exc)
  File "/home/python/.virtualenvs/py3_django_1.11/lib/python3.5/site-packages/rest_framework/views.py", line 443, in handle_exception
    self.raise_uncaught_exception(exc)
  File "/home/python/.virtualenvs/py3_django_1.11/lib/python3.5/site-packages/rest_framework/views.py", line 480, in dispatch
    response = handler(request, *args, **kwargs)
  File "/home/python/Desktop/meiduo/ManyBeautifulMall/ManyBeautiful/ManyBeautifulMall/apps/users/views.py", line 24, in get
    count = User.object.filter(username=username).count()
AttributeError: type object 'User' has no attribute 'object'
INFO 2018-10-24 11:32:25,207 basehttp 124 "OPTIONS /users/ HTTP/1.1" 200 0
INFO 2018-10-24 11:32:25,219 basehttp 124 "GET /mobiles/17605272633/count/ HTTP/1.1" 200 34
ERROR 2018-10-24 11:32:25,244 basehttp 124 "GET /usernames/00000000/count/ HTTP/1.1" 500 18356
ERROR 2018-10-24 11:32:25,336 exception 135 Internal Server Error: /usernames/00000000/count/
Traceback (most recent call last):
  File "/home/python/.virtualenvs/py3_django_1.11/lib/python3.5/site-packages/django/core/handlers/exception.py", line 41, in inner
    response = get_response(request)
  File "/home/python/.virtualenvs/py3_django_1.11/lib/python3.5/site-packages/django/core/handlers/base.py", line 187, in _get_response
    response = self.process_exception_by_middleware(e, request)
  File "/home/python/.virtualenvs/py3_django_1.11/lib/python3.5/site-packages/django/core/handlers/base.py", line 185, in _get_response
    response = wrapped_callback(request, *callback_args, **callback_kwargs)
  File "/home/python/.virtualenvs/py3_django_1.11/lib/python3.5/site-packages/django/views/decorators/csrf.py", line 58, in wrapped_view
    return view_func(*args, **kwargs)
  File "/home/python/.virtualenvs/py3_django_1.11/lib/python3.5/site-packages/django/views/generic/base.py", line 68, in view
    return self.dispatch(request, *args, **kwargs)
  File "/home/python/.virtualenvs/py3_django_1.11/lib/python3.5/site-packages/rest_framework/views.py", line 483, in dispatch
    response = self.handle_exception(exc)
  File "/home/python/.virtualenvs/py3_django_1.11/lib/python3.5/site-packages/rest_framework/views.py", line 443, in handle_exception
    self.raise_uncaught_exception(exc)
  File "/home/python/.virtualenvs/py3_django_1.11/lib/python3.5/site-packages/rest_framework/views.py", line 480, in dispatch
    response = handler(request, *args, **kwargs)
  File "/home/python/Desktop/meiduo/ManyBeautifulMall/ManyBeautiful/ManyBeautifulMall/apps/users/views.py", line 24, in get
    count = User.object.filter(username=username).count()
AttributeError: type object 'User' has no attribute 'object'
INFO 2018-10-24 11:32:25,353 basehttp 124 "OPTIONS /users/ HTTP/1.1" 200 0
ERROR 2018-10-24 11:32:25,369 basehttp 124 "GET /usernames/00000000/count/ HTTP/1.1" 500 18356
ERROR 2018-10-24 11:32:25,476 exception 135 Internal Server Error: /usernames/00000000/count/
Traceback (most recent call last):
  File "/home/python/.virtualenvs/py3_django_1.11/lib/python3.5/site-packages/django/core/handlers/exception.py", line 41, in inner
    response = get_response(request)
  File "/home/python/.virtualenvs/py3_django_1.11/lib/python3.5/site-packages/django/core/handlers/base.py", line 187, in _get_response
    response = self.process_exception_by_middleware(e, request)
  File "/home/python/.virtualenvs/py3_django_1.11/lib/python3.5/site-packages/django/core/handlers/base.py", line 185, in _get_response
    response = wrapped_callback(request, *callback_args, **callback_kwargs)
  File "/home/python/.virtualenvs/py3_django_1.11/lib/python3.5/site-packages/django/views/decorators/csrf.py", line 58, in wrapped_view
    return view_func(*args, **kwargs)
  File "/home/python/.virtualenvs/py3_django_1.11/lib/python3.5/site-packages/django/views/generic/base.py", line 68, in view
    return self.dispatch(request, *args, **kwargs)
  File "/home/python/.virtualenvs/py3_django_1.11/lib/python3.5/site-packages/rest_framework/views.py", line 483, in dispatch
    response = self.handle_exception(exc)
  File "/home/python/.virtualenvs/py3_django_1.11/lib/python3.5/site-packages/rest_framework/views.py", line 443, in handle_exception
    self.raise_uncaught_exception(exc)
  File "/home/python/.virtualenvs/py3_django_1.11/lib/python3.5/site-packages/rest_framework/views.py", line 480, in dispatch
    response = handler(request, *args, **kwargs)
  File "/home/python/Desktop/meiduo/ManyBeautifulMall/ManyBeautiful/ManyBeautifulMall/apps/users/views.py", line 24, in get
    count = User.object.filter(username=username).count()
AttributeError: type object 'User' has no attribute 'object'
INFO 2018-10-24 11:32:25,487 basehttp 124 "OPTIONS /users/ HTTP/1.1" 200 0
INFO 2018-10-24 11:32:25,511 basehttp 124 "GET /mobiles/17605272633/count/ HTTP/1.1" 200 34
INFO 2018-10-24 11:32:25,540 basehttp 124 "GET /mobiles/17605272633/count/ HTTP/1.1" 200 34
ERROR 2018-10-24 11:32:25,543 basehttp 124 "GET /usernames/00000000/count/ HTTP/1.1" 500 18356
ERROR 2018-10-24 11:32:25,619 exception 135 Internal Server Error: /usernames/00000000/count/
Traceback (most recent call last):
  File "/home/python/.virtualenvs/py3_django_1.11/lib/python3.5/site-packages/django/core/handlers/exception.py", line 41, in inner
    response = get_response(request)
  File "/home/python/.virtualenvs/py3_django_1.11/lib/python3.5/site-packages/django/core/handlers/base.py", line 187, in _get_response
    response = self.process_exception_by_middleware(e, request)
  File "/home/python/.virtualenvs/py3_django_1.11/lib/python3.5/site-packages/django/core/handlers/base.py", line 185, in _get_response
    response = wrapped_callback(request, *callback_args, **callback_kwargs)
  File "/home/python/.virtualenvs/py3_django_1.11/lib/python3.5/site-packages/django/views/decorators/csrf.py", line 58, in wrapped_view
    return view_func(*args, **kwargs)
  File "/home/python/.virtualenvs/py3_django_1.11/lib/python3.5/site-packages/django/views/generic/base.py", line 68, in view
    return self.dispatch(request, *args, **kwargs)
  File "/home/python/.virtualenvs/py3_django_1.11/lib/python3.5/site-packages/rest_framework/views.py", line 483, in dispatch
    response = self.handle_exception(exc)
  File "/home/python/.virtualenvs/py3_django_1.11/lib/python3.5/site-packages/rest_framework/views.py", line 443, in handle_exception
    self.raise_uncaught_exception(exc)
  File "/home/python/.virtualenvs/py3_django_1.11/lib/python3.5/site-packages/rest_framework/views.py", line 480, in dispatch
    response = handler(request, *args, **kwargs)
  File "/home/python/Desktop/meiduo/ManyBeautifulMall/ManyBeautiful/ManyBeautifulMall/apps/users/views.py", line 24, in get
    count = User.object.filter(username=username).count()
AttributeError: type object 'User' has no attribute 'object'
INFO 2018-10-24 11:32:25,700 basehttp 124 "OPTIONS /users/ HTTP/1.1" 200 0
INFO 2018-10-24 11:32:25,707 basehttp 124 "GET /mobiles/17605272633/count/ HTTP/1.1" 200 34
ERROR 2018-10-24 11:32:25,748 basehttp 124 "GET /usernames/00000000/count/ HTTP/1.1" 500 18356
ERROR 2018-10-24 11:32:25,770 exception 135 Internal Server Error: /usernames/00000000/count/
Traceback (most recent call last):
  File "/home/python/.virtualenvs/py3_django_1.11/lib/python3.5/site-packages/django/core/handlers/exception.py", line 41, in inner
    response = get_response(request)
  File "/home/python/.virtualenvs/py3_django_1.11/lib/python3.5/site-packages/django/core/handlers/base.py", line 187, in _get_response
    response = self.process_exception_by_middleware(e, request)
  File "/home/python/.virtualenvs/py3_django_1.11/lib/python3.5/site-packages/django/core/handlers/base.py", line 185, in _get_response
    response = wrapped_callback(request, *callback_args, **callback_kwargs)
  File "/home/python/.virtualenvs/py3_django_1.11/lib/python3.5/site-packages/django/views/decorators/csrf.py", line 58, in wrapped_view
    return view_func(*args, **kwargs)
  File "/home/python/.virtualenvs/py3_django_1.11/lib/python3.5/site-packages/django/views/generic/base.py", line 68, in view
    return self.dispatch(request, *args, **kwargs)
  File "/home/python/.virtualenvs/py3_django_1.11/lib/python3.5/site-packages/rest_framework/views.py", line 483, in dispatch
    response = self.handle_exception(exc)
  File "/home/python/.virtualenvs/py3_django_1.11/lib/python3.5/site-packages/rest_framework/views.py", line 443, in handle_exception
    self.raise_uncaught_exception(exc)
  File "/home/python/.virtualenvs/py3_django_1.11/lib/python3.5/site-packages/rest_framework/views.py", line 480, in dispatch
    response = handler(request, *args, **kwargs)
  File "/home/python/Desktop/meiduo/ManyBeautifulMall/ManyBeautiful/ManyBeautifulMall/apps/users/views.py", line 24, in get
    count = User.object.filter(username=username).count()
AttributeError: type object 'User' has no attribute 'object'
INFO 2018-10-24 11:32:25,800 basehttp 124 "OPTIONS /users/ HTTP/1.1" 200 0
INFO 2018-10-24 11:32:25,808 basehttp 124 "GET /mobiles/17605272633/count/ HTTP/1.1" 200 34
ERROR 2018-10-24 11:32:25,818 basehttp 124 "GET /usernames/00000000/count/ HTTP/1.1" 500 18356
ERROR 2018-10-24 11:32:25,922 exception 135 Internal Server Error: /usernames/00000000/count/
Traceback (most recent call last):
  File "/home/python/.virtualenvs/py3_django_1.11/lib/python3.5/site-packages/django/core/handlers/exception.py", line 41, in inner
    response = get_response(request)
  File "/home/python/.virtualenvs/py3_django_1.11/lib/python3.5/site-packages/django/core/handlers/base.py", line 187, in _get_response
    response = self.process_exception_by_middleware(e, request)
  File "/home/python/.virtualenvs/py3_django_1.11/lib/python3.5/site-packages/django/core/handlers/base.py", line 185, in _get_response
    response = wrapped_callback(request, *callback_args, **callback_kwargs)
  File "/home/python/.virtualenvs/py3_django_1.11/lib/python3.5/site-packages/django/views/decorators/csrf.py", line 58, in wrapped_view
    return view_func(*args, **kwargs)
  File "/home/python/.virtualenvs/py3_django_1.11/lib/python3.5/site-packages/django/views/generic/base.py", line 68, in view
    return self.dispatch(request, *args, **kwargs)
  File "/home/python/.virtualenvs/py3_django_1.11/lib/python3.5/site-packages/rest_framework/views.py", line 483, in dispatch
    response = self.handle_exception(exc)
  File "/home/python/.virtualenvs/py3_django_1.11/lib/python3.5/site-packages/rest_framework/views.py", line 443, in handle_exception
    self.raise_uncaught_exception(exc)
  File "/home/python/.virtualenvs/py3_django_1.11/lib/python3.5/site-packages/rest_framework/views.py", line 480, in dispatch
    response = handler(request, *args, **kwargs)
  File "/home/python/Desktop/meiduo/ManyBeautifulMall/ManyBeautiful/ManyBeautifulMall/apps/users/views.py", line 24, in get
    count = User.object.filter(username=username).count()
AttributeError: type object 'User' has no attribute 'object'
INFO 2018-10-24 11:32:25,944 basehttp 124 "OPTIONS /users/ HTTP/1.1" 200 0
INFO 2018-10-24 11:32:25,950 basehttp 124 "GET /mobiles/17605272633/count/ HTTP/1.1" 200 34
ERROR 2018-10-24 11:32:25,971 basehttp 124 "GET /usernames/00000000/count/ HTTP/1.1" 500 18356
INFO 2018-10-24 11:33:48,680 basehttp 124 "GET /usernames/00000000/count/ HTTP/1.1" 200 33
INFO 2018-10-24 11:33:57,262 basehttp 124 "GET /mobiles/17605272633/count/ HTTP/1.1" 200 34
INFO 2018-10-24 11:34:36,297 basehttp 124 "GET /mobiles/17605272633/count/ HTTP/1.1" 200 34
INFO 2018-10-24 11:34:36,316 basehttp 124 "GET /sms_code/17605272633/ HTTP/1.1" 200 16
INFO 2018-10-24 11:35:01,489 basehttp 124 "OPTIONS /users/ HTTP/1.1" 200 0
INFO 2018-10-24 11:35:01,583 basehttp 124 "GET /usernames/00000000/count/ HTTP/1.1" 200 33
INFO 2018-10-24 11:35:01,588 basehttp 124 "GET /mobiles/17605272633/count/ HTTP/1.1" 200 34
INFO 2018-10-24 11:35:03,606 basehttp 124 "OPTIONS /users/ HTTP/1.1" 200 0
INFO 2018-10-24 11:35:03,726 basehttp 124 "GET /usernames/00000000/count/ HTTP/1.1" 200 33
INFO 2018-10-24 11:35:03,733 basehttp 124 "GET /mobiles/17605272633/count/ HTTP/1.1" 200 34
INFO 2018-10-24 11:35:13,525 basehttp 124 "OPTIONS /users/ HTTP/1.1" 200 0
INFO 2018-10-24 11:35:13,580 basehttp 124 "GET /usernames/00000000/count/ HTTP/1.1" 200 33
INFO 2018-10-24 11:35:13,592 basehttp 124 "GET /mobiles/17605272633/count/ HTTP/1.1" 200 34
INFO 2018-10-24 11:35:14,079 basehttp 124 "OPTIONS /users/ HTTP/1.1" 200 0
INFO 2018-10-24 11:35:14,085 basehttp 124 "GET /usernames/00000000/count/ HTTP/1.1" 200 33
INFO 2018-10-24 11:35:14,094 basehttp 124 "GET /mobiles/17605272633/count/ HTTP/1.1" 200 34
INFO 2018-10-24 11:35:14,197 basehttp 124 "OPTIONS /users/ HTTP/1.1" 200 0
INFO 2018-10-24 11:35:14,201 basehttp 124 "GET /usernames/00000000/count/ HTTP/1.1" 200 33
INFO 2018-10-24 11:35:14,210 basehttp 124 "GET /mobiles/17605272633/count/ HTTP/1.1" 200 34
INFO 2018-10-24 11:35:14,328 basehttp 124 "OPTIONS /users/ HTTP/1.1" 200 0
INFO 2018-10-24 11:35:14,342 basehttp 124 "GET /usernames/00000000/count/ HTTP/1.1" 200 33
INFO 2018-10-24 11:35:14,360 basehttp 124 "GET /mobiles/17605272633/count/ HTTP/1.1" 200 34
INFO 2018-10-24 11:35:14,471 basehttp 124 "OPTIONS /users/ HTTP/1.1" 200 0
INFO 2018-10-24 11:35:14,497 basehttp 124 "GET /usernames/00000000/count/ HTTP/1.1" 200 33
INFO 2018-10-24 11:35:14,503 basehttp 124 "GET /mobiles/17605272633/count/ HTTP/1.1" 200 34
INFO 2018-10-24 11:35:14,656 basehttp 124 "GET /usernames/00000000/count/ HTTP/1.1" 200 33
INFO 2018-10-24 11:35:14,658 basehttp 124 "OPTIONS /users/ HTTP/1.1" 200 0
INFO 2018-10-24 11:35:14,671 basehttp 124 "GET /mobiles/17605272633/count/ HTTP/1.1" 200 34
INFO 2018-10-24 11:35:49,222 basehttp 124 "GET /usernames/00000000/count/ HTTP/1.1" 200 33
INFO 2018-10-24 11:36:02,187 basehttp 124 "GET /usernames/00000000/count/ HTTP/1.1" 200 33
INFO 2018-10-24 11:37:54,183 basehttp 124 "GET /usernames/00000000/count/ HTTP/1.1" 200 33
INFO 2018-10-24 11:37:59,597 basehttp 124 "GET /usernames/00000000/count/ HTTP/1.1" 200 33
INFO 2018-10-24 11:37:59,761 basehttp 124 "OPTIONS /users/ HTTP/1.1" 200 0
INFO 2018-10-24 11:37:59,860 basehttp 124 "GET /mobiles/17605272633/count/ HTTP/1.1" 200 34
INFO 2018-10-24 11:37:59,867 basehttp 124 "GET /usernames/00000000/count/ HTTP/1.1" 200 33
INFO 2018-10-24 11:39:19,460 basehttp 124 "GET /usernames/00000000/count/ HTTP/1.1" 200 33
INFO 2018-10-24 11:39:29,082 basehttp 124 "GET /mobiles/17605272633/count/ HTTP/1.1" 200 34
INFO 2018-10-24 11:39:29,150 basehttp 124 "GET /mobiles/17605272633/count/ HTTP/1.1" 200 34
INFO 2018-10-24 11:39:29,183 basehttp 124 "GET /sms_code/17605272633/ HTTP/1.1" 200 16
INFO 2018-10-24 11:40:50,443 basehttp 124 "GET /usernames/00000000/count/ HTTP/1.1" 200 5305
INFO 2018-10-24 11:40:50,603 basehttp 124 "GET /static/rest_framework/css/default.css HTTP/1.1" 200 1131
INFO 2018-10-24 11:40:50,604 basehttp 124 "GET /static/rest_framework/js/jquery-3.3.1.min.js HTTP/1.1" 200 86927
INFO 2018-10-24 11:40:50,608 basehttp 124 "GET /static/rest_framework/js/ajax-form.js HTTP/1.1" 200 3597
INFO 2018-10-24 11:40:50,626 basehttp 124 "GET /static/rest_framework/css/bootstrap.min.css HTTP/1.1" 200 121200
INFO 2018-10-24 11:40:50,627 basehttp 124 "GET /static/rest_framework/css/prettify.css HTTP/1.1" 200 817
INFO 2018-10-24 11:40:50,631 basehttp 124 "GET /static/rest_framework/js/csrf.js HTTP/1.1" 200 1735
INFO 2018-10-24 11:40:50,631 basehttp 124 "GET /static/rest_framework/css/bootstrap-tweaks.css HTTP/1.1" 200 3385
INFO 2018-10-24 11:40:50,635 basehttp 124 "GET /static/rest_framework/js/bootstrap.min.js HTTP/1.1" 200 37045
INFO 2018-10-24 11:40:50,690 basehttp 124 "GET /static/rest_framework/js/prettify-min.js HTTP/1.1" 200 13632
INFO 2018-10-24 11:40:50,696 basehttp 124 "GET /static/rest_framework/js/default.js HTTP/1.1" 200 1262
INFO 2018-10-24 11:40:51,057 basehttp 124 "GET /static/rest_framework/img/grid.png HTTP/1.1" 200 1458
WARNING 2018-10-24 11:40:51,422 base 152 Not Found: /favicon.ico
WARNING 2018-10-24 11:40:51,430 basehttp 124 "GET /favicon.ico HTTP/1.1" 404 2713
INFO 2018-10-24 11:42:59,505 basehttp 124 "GET /usernames/00000000/count/ HTTP/1.1" 200 33
INFO 2018-10-24 11:43:15,125 basehttp 124 "GET /mobiles/17605272633/count/ HTTP/1.1" 200 34
INFO 2018-10-24 11:43:15,168 basehttp 124 "GET /mobiles/17605272633/count/ HTTP/1.1" 200 34
INFO 2018-10-24 11:43:15,172 basehttp 124 "GET /sms_code/17605272633/ HTTP/1.1" 200 16
INFO 2018-10-24 11:43:26,994 basehttp 124 "OPTIONS /users/ HTTP/1.1" 200 0
INFO 2018-10-24 11:43:27,014 basehttp 124 "GET /usernames/00000000/count/ HTTP/1.1" 200 33
INFO 2018-10-24 11:43:27,025 basehttp 124 "GET /mobiles/17605272633/count/ HTTP/1.1" 200 34
INFO 2018-10-24 11:43:27,373 basehttp 124 "POST /users/ HTTP/1.1" 201 53
INFO 2018-10-24 18:17:31,564 basehttp 124 "GET /mobiles/17605272633/count/ HTTP/1.1" 200 34
INFO 2018-10-24 18:17:31,566 basehttp 124 "GET /usernames/00000000/count/ HTTP/1.1" 200 33
INFO 2018-10-24 18:17:32,036 basehttp 124 "GET /sms_code/17605272633/ HTTP/1.1" 200 16
INFO 2018-10-24 18:17:41,820 basehttp 124 "OPTIONS /users/ HTTP/1.1" 200 0
INFO 2018-10-24 18:17:41,898 basehttp 124 "GET /usernames/00000000/count/ HTTP/1.1" 200 33
INFO 2018-10-24 18:17:41,901 basehttp 124 "GET /mobiles/17605272633/count/ HTTP/1.1" 200 34
INFO 2018-10-24 18:17:42,098 basehttp 124 "POST /users/ HTTP/1.1" 201 229
INFO 2018-10-24 20:11:20,101 basehttp 124 "OPTIONS /authorizations/ HTTP/1.1" 200 0
INFO 2018-10-24 20:11:20,408 basehttp 124 "POST /authorizations/ HTTP/1.1" 200 211
INFO 2018-10-24 20:11:32,221 basehttp 124 "POST /authorizations/ HTTP/1.1" 200 211
INFO 2018-10-24 20:31:16,994 basehttp 124 "OPTIONS /authorizations/ HTTP/1.1" 200 0
INFO 2018-10-24 20:31:17,439 basehttp 124 "POST /authorizations/ HTTP/1.1" 200 211
INFO 2018-10-26 12:32:31,523 basehttp 124 "OPTIONS /user/ HTTP/1.1" 200 0
WARNING 2018-10-26 12:32:31,896 base 152 Not Found: /user/
WARNING 2018-10-26 12:32:31,903 basehttp 124 "GET /user/ HTTP/1.1" 404 2967
WARNING 2018-10-26 12:32:35,335 base 152 Not Found: /user/
WARNING 2018-10-26 12:32:35,341 basehttp 124 "GET /user/ HTTP/1.1" 404 2967
INFO 2018-10-26 12:32:53,384 basehttp 124 "OPTIONS /authorizations/ HTTP/1.1" 200 0
INFO 2018-10-26 12:32:53,560 basehttp 124 "POST /authorizations/ HTTP/1.1" 200 211
WARNING 2018-10-26 12:32:56,509 base 152 Not Found: /user/
WARNING 2018-10-26 12:32:56,512 basehttp 124 "GET /user/ HTTP/1.1" 404 2967
INFO 2018-10-26 12:34:09,485 basehttp 124 "GET /user/ HTTP/1.1" 200 85
INFO 2018-10-26 12:34:09,511 basehttp 124 "OPTIONS /browse_histories/ HTTP/1.1" 200 0
WARNING 2018-10-26 12:34:09,536 base 152 Not Found: /browse_histories/
WARNING 2018-10-26 12:34:09,543 basehttp 124 "GET /browse_histories/ HTTP/1.1" 404 3158
INFO 2018-10-26 13:27:39,831 basehttp 124 "OPTIONS /authorizations/ HTTP/1.1" 200 0
INFO 2018-10-26 13:27:59,531 basehttp 124 "OPTIONS /authorizations/ HTTP/1.1" 200 0
INFO 2018-10-26 13:28:00,165 basehttp 124 "POST /authorizations/ HTTP/1.1" 200 211
INFO 2018-10-26 13:28:03,902 basehttp 124 "OPTIONS /user/ HTTP/1.1" 200 0
INFO 2018-10-26 13:28:04,190 basehttp 124 "GET /user/ HTTP/1.1" 200 85
INFO 2018-10-26 13:28:04,207 basehttp 124 "OPTIONS /browse_histories/ HTTP/1.1" 200 0
WARNING 2018-10-26 13:28:04,238 base 152 Not Found: /browse_histories/
WARNING 2018-10-26 13:28:04,244 basehttp 124 "GET /browse_histories/ HTTP/1.1" 404 3158
INFO 2018-10-26 20:09:59,534 basehttp 124 "OPTIONS /authorizations/ HTTP/1.1" 200 0
INFO 2018-10-26 20:10:16,294 basehttp 124 "OPTIONS /authorizations/ HTTP/1.1" 200 0
INFO 2018-10-26 20:10:16,660 basehttp 124 "POST /authorizations/ HTTP/1.1" 200 211
INFO 2018-10-26 20:10:20,689 basehttp 124 "OPTIONS /user/ HTTP/1.1" 200 0
INFO 2018-10-26 20:10:20,824 basehttp 124 "GET /user/ HTTP/1.1" 200 85
INFO 2018-10-26 20:10:20,890 basehttp 124 "OPTIONS /browse_histories/ HTTP/1.1" 200 0
WARNING 2018-10-26 20:10:20,924 base 152 Not Found: /browse_histories/
WARNING 2018-10-26 20:10:20,927 basehttp 124 "GET /browse_histories/ HTTP/1.1" 404 3158
INFO 2018-10-27 00:15:25,596 basehttp 124 "GET /oauth/qq/authorization/?next=/ HTTP/1.1" 200 166
INFO 2018-10-27 00:15:25,981 basehttp 124 "GET /oauth/qq/authorization/?next=/ HTTP/1.1" 200 166
INFO 2018-10-27 00:15:35,492 basehttp 124 "GET /oauth/qq/authorization/?next=/ HTTP/1.1" 200 166
WARNING 2018-10-27 00:22:45,071 base 152 Not Found: /oauth/qq/authorization/
WARNING 2018-10-27 00:22:45,076 basehttp 124 "GET /oauth/qq/authorization/?next=/ HTTP/1.1" 404 3240
WARNING 2018-10-27 00:22:46,256 base 152 Not Found: /oauth/qq/authorization/
WARNING 2018-10-27 00:22:46,259 basehttp 124 "GET /oauth/qq/authorization/?next=/ HTTP/1.1" 404 3240
WARNING 2018-10-27 00:22:47,350 base 152 Not Found: /oauth/qq/authorization/
WARNING 2018-10-27 00:22:47,356 basehttp 124 "GET /oauth/qq/authorization/?next=/ HTTP/1.1" 404 3240
WARNING 2018-10-27 00:22:47,513 base 152 Not Found: /oauth/qq/authorization/
WARNING 2018-10-27 00:22:47,515 basehttp 124 "GET /oauth/qq/authorization/?next=/ HTTP/1.1" 404 3240
WARNING 2018-10-27 00:22:47,681 base 152 Not Found: /oauth/qq/authorization/
WARNING 2018-10-27 00:22:47,688 basehttp 124 "GET /oauth/qq/authorization/?next=/ HTTP/1.1" 404 3240
WARNING 2018-10-27 00:22:47,855 base 152 Not Found: /oauth/qq/authorization/
WARNING 2018-10-27 00:22:47,865 basehttp 124 "GET /oauth/qq/authorization/?next=/ HTTP/1.1" 404 3240
WARNING 2018-10-27 00:22:48,057 base 152 Not Found: /oauth/qq/authorization/
WARNING 2018-10-27 00:22:48,060 basehttp 124 "GET /oauth/qq/authorization/?next=/ HTTP/1.1" 404 3240
WARNING 2018-10-27 00:22:48,164 base 152 Not Found: /oauth/qq/authorization/
WARNING 2018-10-27 00:22:48,167 basehttp 124 "GET /oauth/qq/authorization/?next=/ HTTP/1.1" 404 3240
WARNING 2018-10-27 00:22:48,360 base 152 Not Found: /oauth/qq/authorization/
WARNING 2018-10-27 00:22:48,367 basehttp 124 "GET /oauth/qq/authorization/?next=/ HTTP/1.1" 404 3240
WARNING 2018-10-27 00:22:48,548 base 152 Not Found: /oauth/qq/authorization/
WARNING 2018-10-27 00:22:48,557 basehttp 124 "GET /oauth/qq/authorization/?next=/ HTTP/1.1" 404 3240
WARNING 2018-10-27 00:22:48,627 base 152 Not Found: /oauth/qq/authorization/
WARNING 2018-10-27 00:22:48,631 basehttp 124 "GET /oauth/qq/authorization/?next=/ HTTP/1.1" 404 3240
WARNING 2018-10-27 00:22:48,846 base 152 Not Found: /oauth/qq/authorization/
WARNING 2018-10-27 00:22:48,849 basehttp 124 "GET /oauth/qq/authorization/?next=/ HTTP/1.1" 404 3240
WARNING 2018-10-27 00:22:49,012 base 152 Not Found: /oauth/qq/authorization/
WARNING 2018-10-27 00:22:49,018 basehttp 124 "GET /oauth/qq/authorization/?next=/ HTTP/1.1" 404 3240
WARNING 2018-10-27 00:22:49,088 base 152 Not Found: /oauth/qq/authorization/
WARNING 2018-10-27 00:22:49,093 basehttp 124 "GET /oauth/qq/authorization/?next=/ HTTP/1.1" 404 3240
WARNING 2018-10-27 00:22:49,274 base 152 Not Found: /oauth/qq/authorization/
WARNING 2018-10-27 00:22:49,278 basehttp 124 "GET /oauth/qq/authorization/?next=/ HTTP/1.1" 404 3240
WARNING 2018-10-27 00:22:49,465 base 152 Not Found: /oauth/qq/authorization/
WARNING 2018-10-27 00:22:49,479 basehttp 124 "GET /oauth/qq/authorization/?next=/ HTTP/1.1" 404 3240
WARNING 2018-10-27 00:22:49,559 base 152 Not Found: /oauth/qq/authorization/
WARNING 2018-10-27 00:22:49,568 basehttp 124 "GET /oauth/qq/authorization/?next=/ HTTP/1.1" 404 3240
WARNING 2018-10-27 00:22:55,176 base 152 Not Found: /oauth/qq/authorization/
WARNING 2018-10-27 00:22:55,178 basehttp 124 "GET /oauth/qq/authorization/?next=/ HTTP/1.1" 404 3240
WARNING 2018-10-27 00:22:56,384 base 152 Not Found: /oauth/qq/authorization/
WARNING 2018-10-27 00:22:56,392 basehttp 124 "GET /oauth/qq/authorization/?next=/ HTTP/1.1" 404 3240
WARNING 2018-10-27 00:22:56,806 base 152 Not Found: /oauth/qq/authorization/
WARNING 2018-10-27 00:22:56,809 basehttp 124 "GET /oauth/qq/authorization/?next=/ HTTP/1.1" 404 3240
WARNING 2018-10-27 00:22:57,637 base 152 Not Found: /oauth/qq/authorization/
WARNING 2018-10-27 00:22:57,645 basehttp 124 "GET /oauth/qq/authorization/?next=/ HTTP/1.1" 404 3240
WARNING 2018-10-27 00:22:58,488 base 152 Not Found: /oauth/qq/authorization/
WARNING 2018-10-27 00:22:58,495 basehttp 124 "GET /oauth/qq/authorization/?next=/ HTTP/1.1" 404 3240
WARNING 2018-10-27 00:22:59,286 base 152 Not Found: /oauth/qq/authorization/
WARNING 2018-10-27 00:22:59,292 basehttp 124 "GET /oauth/qq/authorization/?next=/ HTTP/1.1" 404 3240
WARNING 2018-10-27 00:22:59,583 base 152 Not Found: /oauth/qq/authorization/
WARNING 2018-10-27 00:22:59,586 basehttp 124 "GET /oauth/qq/authorization/?next=/ HTTP/1.1" 404 3240
INFO 2018-10-27 00:23:23,477 basehttp 124 "GET /oauth/qq/authorization/?next=/ HTTP/1.1" 200 166
INFO 2018-10-27 09:57:36,716 basehttp 124 "GET /oauth/qq/authorization/?next=/ HTTP/1.1" 200 166
INFO 2018-10-27 10:15:08,024 basehttp 124 "GET /oauth/weixin/authorization/?next=/ HTTP/1.1" 200 166
INFO 2018-10-27 10:19:15,433 basehttp 124 "GET /oauth/weixin/authorization/?next=/ HTTP/1.1" 200 166
INFO 2018-10-27 10:19:27,284 basehttp 124 "GET /oauth/weixin/authorization/?next=/ HTTP/1.1" 200 166
INFO 2018-10-27 10:20:20,360 basehttp 124 "GET /oauth/weixin/authorization/?next=/ HTTP/1.1" 200 171
INFO 2018-10-27 10:39:07,110 basehttp 124 "GET /oauth/qq/authorization/?next=/ HTTP/1.1" 200 175
INFO 2018-10-27 10:39:30,005 basehttp 124 "GET /oauth/qq/user/?code=049AA177AAF11B3022CF45AD3ACDB8E5 HTTP/1.1" 200 233
INFO 2018-10-27 10:39:47,765 basehttp 124 "GET /sms_code/17605272633/ HTTP/1.1" 200 16
INFO 2018-10-27 10:40:10,503 basehttp 124 "OPTIONS /oauth/qq/user/ HTTP/1.1" 200 0
ERROR 2018-10-27 10:40:10,743 exception 135 Internal Server Error: /oauth/qq/user/
Traceback (most recent call last):
  File "/home/python/.virtualenvs/py3_django_1.11/lib/python3.5/site-packages/rest_framework/serializers.py", line 940, in create
    instance = ModelClass.objects.create(**validated_data)
  File "/home/python/.virtualenvs/py3_django_1.11/lib/python3.5/site-packages/django/db/models/manager.py", line 85, in manager_method
    return getattr(self.get_queryset(), name)(*args, **kwargs)
  File "/home/python/.virtualenvs/py3_django_1.11/lib/python3.5/site-packages/django/db/models/query.py", line 392, in create
    obj = self.model(**kwargs)
  File "/home/python/.virtualenvs/py3_django_1.11/lib/python3.5/site-packages/django/contrib/auth/base_user.py", line 68, in __init__
    super(AbstractBaseUser, self).__init__(*args, **kwargs)
  File "/home/python/.virtualenvs/py3_django_1.11/lib/python3.5/site-packages/django/db/models/base.py", line 573, in __init__
    raise TypeError("'%s' is an invalid keyword argument for this function" % list(kwargs)[0])
TypeError: 'access_token' is an invalid keyword argument for this function

During handling of the above exception, another exception occurred:

Traceback (most recent call last):
  File "/home/python/.virtualenvs/py3_django_1.11/lib/python3.5/site-packages/django/core/handlers/exception.py", line 41, in inner
    response = get_response(request)
  File "/home/python/.virtualenvs/py3_django_1.11/lib/python3.5/site-packages/django/core/handlers/base.py", line 187, in _get_response
    response = self.process_exception_by_middleware(e, request)
  File "/home/python/.virtualenvs/py3_django_1.11/lib/python3.5/site-packages/django/core/handlers/base.py", line 185, in _get_response
    response = wrapped_callback(request, *callback_args, **callback_kwargs)
  File "/home/python/.virtualenvs/py3_django_1.11/lib/python3.5/site-packages/django/views/decorators/csrf.py", line 58, in wrapped_view
    return view_func(*args, **kwargs)
  File "/home/python/.virtualenvs/py3_django_1.11/lib/python3.5/site-packages/django/views/generic/base.py", line 68, in view
    return self.dispatch(request, *args, **kwargs)
  File "/home/python/.virtualenvs/py3_django_1.11/lib/python3.5/site-packages/rest_framework/views.py", line 483, in dispatch
    response = self.handle_exception(exc)
  File "/home/python/.virtualenvs/py3_django_1.11/lib/python3.5/site-packages/rest_framework/views.py", line 443, in handle_exception
    self.raise_uncaught_exception(exc)
  File "/home/python/.virtualenvs/py3_django_1.11/lib/python3.5/site-packages/rest_framework/views.py", line 480, in dispatch
    response = handler(request, *args, **kwargs)
  File "/home/python/Desktop/meiduomall/ManyBeautifulMall/ManyBeautiful/ManyBeautifulMall/apps/oauth/views.py", line 96, in post
    user = serializer.save()
  File "/home/python/.virtualenvs/py3_django_1.11/lib/python3.5/site-packages/rest_framework/serializers.py", line 214, in save
    self.instance = self.create(validated_data)
  File "/home/python/.virtualenvs/py3_django_1.11/lib/python3.5/site-packages/rest_framework/serializers.py", line 957, in create
    raise TypeError(msg)
TypeError: Got a `TypeError` when calling `User.objects.create()`. This may be because you have a writable field on the serializer class that is not a valid argument to `User.objects.create()`. You may need to make the field read-only, or override the OAuthQQUserSerializer.create() method to handle this correctly.
Original exception was:
 Traceback (most recent call last):
  File "/home/python/.virtualenvs/py3_django_1.11/lib/python3.5/site-packages/rest_framework/serializers.py", line 940, in create
    instance = ModelClass.objects.create(**validated_data)
  File "/home/python/.virtualenvs/py3_django_1.11/lib/python3.5/site-packages/django/db/models/manager.py", line 85, in manager_method
    return getattr(self.get_queryset(), name)(*args, **kwargs)
  File "/home/python/.virtualenvs/py3_django_1.11/lib/python3.5/site-packages/django/db/models/query.py", line 392, in create
    obj = self.model(**kwargs)
  File "/home/python/.virtualenvs/py3_django_1.11/lib/python3.5/site-packages/django/contrib/auth/base_user.py", line 68, in __init__
    super(AbstractBaseUser, self).__init__(*args, **kwargs)
  File "/home/python/.virtualenvs/py3_django_1.11/lib/python3.5/site-packages/django/db/models/base.py", line 573, in __init__
    raise TypeError("'%s' is an invalid keyword argument for this function" % list(kwargs)[0])
TypeError: 'access_token' is an invalid keyword argument for this function

ERROR 2018-10-27 10:40:11,250 basehttp 124 "POST /oauth/qq/user/ HTTP/1.1" 500 23143
INFO 2018-10-27 11:02:27,401 basehttp 124 "GET /oauth/qq/user/?code=5C314A586B2143B32FBF6059F3D99E65 HTTP/1.1" 200 233
INFO 2018-10-27 11:02:38,440 basehttp 124 "GET /sms_code/17605272633/ HTTP/1.1" 200 16
INFO 2018-10-27 11:02:49,012 basehttp 124 "OPTIONS /oauth/qq/user/ HTTP/1.1" 200 0
ERROR 2018-10-27 11:02:49,106 exception 135 Internal Server Error: /oauth/qq/user/
Traceback (most recent call last):
  File "/home/python/.virtualenvs/py3_django_1.11/lib/python3.5/site-packages/rest_framework/serializers.py", line 940, in create
    instance = ModelClass.objects.create(**validated_data)
  File "/home/python/.virtualenvs/py3_django_1.11/lib/python3.5/site-packages/django/db/models/manager.py", line 85, in manager_method
    return getattr(self.get_queryset(), name)(*args, **kwargs)
  File "/home/python/.virtualenvs/py3_django_1.11/lib/python3.5/site-packages/django/db/models/query.py", line 392, in create
    obj = self.model(**kwargs)
  File "/home/python/.virtualenvs/py3_django_1.11/lib/python3.5/site-packages/django/contrib/auth/base_user.py", line 68, in __init__
    super(AbstractBaseUser, self).__init__(*args, **kwargs)
  File "/home/python/.virtualenvs/py3_django_1.11/lib/python3.5/site-packages/django/db/models/base.py", line 573, in __init__
    raise TypeError("'%s' is an invalid keyword argument for this function" % list(kwargs)[0])
TypeError: 'sms_code' is an invalid keyword argument for this function

During handling of the above exception, another exception occurred:

Traceback (most recent call last):
  File "/home/python/.virtualenvs/py3_django_1.11/lib/python3.5/site-packages/django/core/handlers/exception.py", line 41, in inner
    response = get_response(request)
  File "/home/python/.virtualenvs/py3_django_1.11/lib/python3.5/site-packages/django/core/handlers/base.py", line 187, in _get_response
    response = self.process_exception_by_middleware(e, request)
  File "/home/python/.virtualenvs/py3_django_1.11/lib/python3.5/site-packages/django/core/handlers/base.py", line 185, in _get_response
    response = wrapped_callback(request, *callback_args, **callback_kwargs)
  File "/home/python/.virtualenvs/py3_django_1.11/lib/python3.5/site-packages/django/views/decorators/csrf.py", line 58, in wrapped_view
    return view_func(*args, **kwargs)
  File "/home/python/.virtualenvs/py3_django_1.11/lib/python3.5/site-packages/django/views/generic/base.py", line 68, in view
    return self.dispatch(request, *args, **kwargs)
  File "/home/python/.virtualenvs/py3_django_1.11/lib/python3.5/site-packages/rest_framework/views.py", line 483, in dispatch
    response = self.handle_exception(exc)
  File "/home/python/.virtualenvs/py3_django_1.11/lib/python3.5/site-packages/rest_framework/views.py", line 443, in handle_exception
    self.raise_uncaught_exception(exc)
  File "/home/python/.virtualenvs/py3_django_1.11/lib/python3.5/site-packages/rest_framework/views.py", line 480, in dispatch
    response = handler(request, *args, **kwargs)
  File "/home/python/Desktop/meiduomall/ManyBeautifulMall/ManyBeautiful/ManyBeautifulMall/apps/oauth/views.py", line 96, in post
    user = serializer.save()
  File "/home/python/.virtualenvs/py3_django_1.11/lib/python3.5/site-packages/rest_framework/serializers.py", line 214, in save
    self.instance = self.create(validated_data)
  File "/home/python/.virtualenvs/py3_django_1.11/lib/python3.5/site-packages/rest_framework/serializers.py", line 957, in create
    raise TypeError(msg)
TypeError: Got a `TypeError` when calling `User.objects.create()`. This may be because you have a writable field on the serializer class that is not a valid argument to `User.objects.create()`. You may need to make the field read-only, or override the OAuthQQUserSerializer.create() method to handle this correctly.
Original exception was:
 Traceback (most recent call last):
  File "/home/python/.virtualenvs/py3_django_1.11/lib/python3.5/site-packages/rest_framework/serializers.py", line 940, in create
    instance = ModelClass.objects.create(**validated_data)
  File "/home/python/.virtualenvs/py3_django_1.11/lib/python3.5/site-packages/django/db/models/manager.py", line 85, in manager_method
    return getattr(self.get_queryset(), name)(*args, **kwargs)
  File "/home/python/.virtualenvs/py3_django_1.11/lib/python3.5/site-packages/django/db/models/query.py", line 392, in create
    obj = self.model(**kwargs)
  File "/home/python/.virtualenvs/py3_django_1.11/lib/python3.5/site-packages/django/contrib/auth/base_user.py", line 68, in __init__
    super(AbstractBaseUser, self).__init__(*args, **kwargs)
  File "/home/python/.virtualenvs/py3_django_1.11/lib/python3.5/site-packages/django/db/models/base.py", line 573, in __init__
    raise TypeError("'%s' is an invalid keyword argument for this function" % list(kwargs)[0])
TypeError: 'sms_code' is an invalid keyword argument for this function

ERROR 2018-10-27 11:02:49,262 basehttp 124 "POST /oauth/qq/user/ HTTP/1.1" 500 23131
ERROR 2018-10-27 11:03:13,323 exceptions 28 [<oauth.views.QQAuthUserView object at 0x7fed66526128>] (1062, "Duplicate entry '17605272633' for key 'mobile'")
ERROR 2018-10-27 11:03:13,326 basehttp 124 "POST /oauth/qq/user/ HTTP/1.1" 507 35
ERROR 2018-10-27 11:03:16,316 utils 78 code=None msg=None
ERROR 2018-10-27 11:03:16,317 basehttp 124 "GET /oauth/qq/user/?code=5C314A586B2143B32FBF6059F3D99E65 HTTP/1.1" 503 28
INFO 2018-10-27 11:03:32,943 basehttp 124 "GET /oauth/qq/user/?code=29F2F737851C73285F65E56BDBD75092 HTTP/1.1" 200 233
INFO 2018-10-27 11:04:16,891 basehttp 124 "GET /sms_code/17605272633/ HTTP/1.1" 200 16
ERROR 2018-10-27 11:04:26,395 exceptions 28 [<oauth.views.QQAuthUserView object at 0x7fed64897e48>] (1062, "Duplicate entry '17605272633' for key 'mobile'")
ERROR 2018-10-27 11:04:26,396 basehttp 124 "POST /oauth/qq/user/ HTTP/1.1" 507 35
ERROR 2018-10-27 11:05:27,247 exceptions 28 [<oauth.views.QQAuthUserView object at 0x7fed65a23e80>] (1062, "Duplicate entry '17605272633' for key 'mobile'")
ERROR 2018-10-27 11:05:27,310 basehttp 124 "POST /oauth/qq/user/ HTTP/1.1" 507 35
INFO 2018-10-27 11:07:29,873 basehttp 124 "GET /oauth/qq/user/?code=03434B359E5FEDA6A9B9A3CE5972FF3D HTTP/1.1" 200 233
INFO 2018-10-27 11:07:38,017 basehttp 124 "GET /sms_code/17605272633/ HTTP/1.1" 200 16
ERROR 2018-10-27 11:08:00,530 exception 135 Internal Server Error: /oauth/qq/user/
Traceback (most recent call last):
  File "/home/python/.virtualenvs/py3_django_1.11/lib/python3.5/site-packages/django/core/handlers/exception.py", line 41, in inner
    response = get_response(request)
  File "/home/python/.virtualenvs/py3_django_1.11/lib/python3.5/site-packages/django/core/handlers/base.py", line 187, in _get_response
    response = self.process_exception_by_middleware(e, request)
  File "/home/python/.virtualenvs/py3_django_1.11/lib/python3.5/site-packages/django/core/handlers/base.py", line 185, in _get_response
    response = wrapped_callback(request, *callback_args, **callback_kwargs)
  File "/home/python/.virtualenvs/py3_django_1.11/lib/python3.5/site-packages/django/views/decorators/csrf.py", line 58, in wrapped_view
    return view_func(*args, **kwargs)
  File "/home/python/.virtualenvs/py3_django_1.11/lib/python3.5/site-packages/django/views/generic/base.py", line 68, in view
    return self.dispatch(request, *args, **kwargs)
  File "/home/python/.virtualenvs/py3_django_1.11/lib/python3.5/site-packages/rest_framework/views.py", line 483, in dispatch
    response = self.handle_exception(exc)
  File "/home/python/.virtualenvs/py3_django_1.11/lib/python3.5/site-packages/rest_framework/views.py", line 443, in handle_exception
    self.raise_uncaught_exception(exc)
  File "/home/python/.virtualenvs/py3_django_1.11/lib/python3.5/site-packages/rest_framework/views.py", line 480, in dispatch
    response = handler(request, *args, **kwargs)
  File "/home/python/Desktop/meiduomall/ManyBeautifulMall/ManyBeautiful/ManyBeautifulMall/apps/oauth/views.py", line 95, in post
    serializer.is_valid(raise_exception=True)
  File "/home/python/.virtualenvs/py3_django_1.11/lib/python3.5/site-packages/rest_framework/serializers.py", line 236, in is_valid
    self._validated_data = self.run_validation(self.initial_data)
  File "/home/python/.virtualenvs/py3_django_1.11/lib/python3.5/site-packages/rest_framework/serializers.py", line 437, in run_validation
    value = self.validate(value)
  File "/home/python/Desktop/meiduomall/ManyBeautifulMall/ManyBeautiful/ManyBeautifulMall/apps/oauth/serializers.py", line 121, in validate
    openid = OAuthQQ.check_seve_user_token(access_token)
  File "/home/python/Desktop/meiduomall/ManyBeautifulMall/ManyBeautiful/ManyBeautifulMall/apps/oauth/utils.py", line 131, in check_seve_user_token
    serializer = Serializer(settings.SERCET_KEY, expires_in=constants.SAVE_QQ_USER_TOKEN_EXPIRES)
  File "/home/python/.virtualenvs/py3_django_1.11/lib/python3.5/site-packages/django/conf/__init__.py", line 57, in __getattr__
    val = getattr(self._wrapped, name)
AttributeError: 'Settings' object has no attribute 'SERCET_KEY'
ERROR 2018-10-27 11:08:00,656 basehttp 124 "POST /oauth/qq/user/ HTTP/1.1" 500 19981
INFO 2018-10-27 11:15:19,743 basehttp 124 "GET /oauth/qq/user/?code=356D7BBED7FFD5457C88A4301A718172 HTTP/1.1" 200 233
INFO 2018-10-27 11:15:26,932 basehttp 124 "GET /sms_code/17605272633/ HTTP/1.1" 200 16
INFO 2018-10-27 11:15:37,911 basehttp 124 "OPTIONS /oauth/qq/user/ HTTP/1.1" 200 0
ERROR 2018-10-27 11:15:37,929 exception 135 Internal Server Error: /oauth/qq/user/
Traceback (most recent call last):
  File "/home/python/.virtualenvs/py3_django_1.11/lib/python3.5/site-packages/django/core/handlers/exception.py", line 41, in inner
    response = get_response(request)
  File "/home/python/.virtualenvs/py3_django_1.11/lib/python3.5/site-packages/django/core/handlers/base.py", line 187, in _get_response
    response = self.process_exception_by_middleware(e, request)
  File "/home/python/.virtualenvs/py3_django_1.11/lib/python3.5/site-packages/django/core/handlers/base.py", line 185, in _get_response
    response = wrapped_callback(request, *callback_args, **callback_kwargs)
  File "/home/python/.virtualenvs/py3_django_1.11/lib/python3.5/site-packages/django/views/decorators/csrf.py", line 58, in wrapped_view
    return view_func(*args, **kwargs)
  File "/home/python/.virtualenvs/py3_django_1.11/lib/python3.5/site-packages/django/views/generic/base.py", line 68, in view
    return self.dispatch(request, *args, **kwargs)
  File "/home/python/.virtualenvs/py3_django_1.11/lib/python3.5/site-packages/rest_framework/views.py", line 483, in dispatch
    response = self.handle_exception(exc)
  File "/home/python/.virtualenvs/py3_django_1.11/lib/python3.5/site-packages/rest_framework/views.py", line 443, in handle_exception
    self.raise_uncaught_exception(exc)
  File "/home/python/.virtualenvs/py3_django_1.11/lib/python3.5/site-packages/rest_framework/views.py", line 480, in dispatch
    response = handler(request, *args, **kwargs)
  File "/home/python/Desktop/meiduomall/ManyBeautifulMall/ManyBeautiful/ManyBeautifulMall/apps/oauth/views.py", line 95, in post
    serializer.is_valid(raise_exception=True)
  File "/home/python/.virtualenvs/py3_django_1.11/lib/python3.5/site-packages/rest_framework/serializers.py", line 236, in is_valid
    self._validated_data = self.run_validation(self.initial_data)
  File "/home/python/.virtualenvs/py3_django_1.11/lib/python3.5/site-packages/rest_framework/serializers.py", line 437, in run_validation
    value = self.validate(value)
  File "/home/python/Desktop/meiduomall/ManyBeautifulMall/ManyBeautiful/ManyBeautifulMall/apps/oauth/serializers.py", line 41, in validate
    openid = OAuthQQ.check_seve_user_token(access_token)
  File "/home/python/Desktop/meiduomall/ManyBeautifulMall/ManyBeautiful/ManyBeautifulMall/apps/oauth/utils.py", line 131, in check_seve_user_token
    serializer = Serializer(settings.SERCET_KEY, expires_in=constants.SAVE_QQ_USER_TOKEN_EXPIRES)
  File "/home/python/.virtualenvs/py3_django_1.11/lib/python3.5/site-packages/django/conf/__init__.py", line 57, in __getattr__
    val = getattr(self._wrapped, name)
AttributeError: 'Settings' object has no attribute 'SERCET_KEY'
ERROR 2018-10-27 11:15:38,022 basehttp 124 "POST /oauth/qq/user/ HTTP/1.1" 500 19980
INFO 2018-10-27 11:23:10,652 basehttp 124 "GET /oauth/qq/user/?code=D8167C39FF3E11ECE1E216B9AC01F6F9 HTTP/1.1" 200 233
INFO 2018-10-27 11:23:17,704 basehttp 124 "GET /sms_code/17605272633/ HTTP/1.1" 200 16
ERROR 2018-10-27 11:23:35,304 exception 135 Internal Server Error: /oauth/qq/user/
Traceback (most recent call last):
  File "/home/python/.virtualenvs/py3_django_1.11/lib/python3.5/site-packages/django/core/handlers/exception.py", line 41, in inner
    response = get_response(request)
  File "/home/python/.virtualenvs/py3_django_1.11/lib/python3.5/site-packages/django/core/handlers/base.py", line 187, in _get_response
    response = self.process_exception_by_middleware(e, request)
  File "/home/python/.virtualenvs/py3_django_1.11/lib/python3.5/site-packages/django/core/handlers/base.py", line 185, in _get_response
    response = wrapped_callback(request, *callback_args, **callback_kwargs)
  File "/home/python/.virtualenvs/py3_django_1.11/lib/python3.5/site-packages/django/views/decorators/csrf.py", line 58, in wrapped_view
    return view_func(*args, **kwargs)
  File "/home/python/.virtualenvs/py3_django_1.11/lib/python3.5/site-packages/django/views/generic/base.py", line 68, in view
    return self.dispatch(request, *args, **kwargs)
  File "/home/python/.virtualenvs/py3_django_1.11/lib/python3.5/site-packages/rest_framework/views.py", line 483, in dispatch
    response = self.handle_exception(exc)
  File "/home/python/.virtualenvs/py3_django_1.11/lib/python3.5/site-packages/rest_framework/views.py", line 443, in handle_exception
    self.raise_uncaught_exception(exc)
  File "/home/python/.virtualenvs/py3_django_1.11/lib/python3.5/site-packages/rest_framework/views.py", line 480, in dispatch
    response = handler(request, *args, **kwargs)
  File "/home/python/Desktop/meiduomall/ManyBeautifulMall/ManyBeautiful/ManyBeautifulMall/apps/oauth/views.py", line 95, in post
    serializer.is_valid()
  File "/home/python/.virtualenvs/py3_django_1.11/lib/python3.5/site-packages/rest_framework/serializers.py", line 236, in is_valid
    self._validated_data = self.run_validation(self.initial_data)
  File "/home/python/.virtualenvs/py3_django_1.11/lib/python3.5/site-packages/rest_framework/serializers.py", line 437, in run_validation
    value = self.validate(value)
  File "/home/python/Desktop/meiduomall/ManyBeautifulMall/ManyBeautiful/ManyBeautifulMall/apps/oauth/serializers.py", line 51, in validate
    openid = OAuthQQ.check_seve_user_token(access_token)
  File "/home/python/Desktop/meiduomall/ManyBeautifulMall/ManyBeautiful/ManyBeautifulMall/apps/oauth/utils.py", line 131, in check_seve_user_token
    serializer = Serializer(settings.SERCET_KEY, expires_in=constants.SAVE_QQ_USER_TOKEN_EXPIRES)
  File "/home/python/.virtualenvs/py3_django_1.11/lib/python3.5/site-packages/django/conf/__init__.py", line 57, in __getattr__
    val = getattr(self._wrapped, name)
AttributeError: 'Settings' object has no attribute 'SERCET_KEY'
ERROR 2018-10-27 11:23:35,365 basehttp 124 "POST /oauth/qq/user/ HTTP/1.1" 500 19960
ERROR 2018-10-27 11:24:25,855 exception 135 Internal Server Error: /oauth/qq/user/
Traceback (most recent call last):
  File "/home/python/.virtualenvs/py3_django_1.11/lib/python3.5/site-packages/django/core/handlers/exception.py", line 41, in inner
    response = get_response(request)
  File "/home/python/.virtualenvs/py3_django_1.11/lib/python3.5/site-packages/django/core/handlers/base.py", line 187, in _get_response
    response = self.process_exception_by_middleware(e, request)
  File "/home/python/.virtualenvs/py3_django_1.11/lib/python3.5/site-packages/django/core/handlers/base.py", line 185, in _get_response
    response = wrapped_callback(request, *callback_args, **callback_kwargs)
  File "/home/python/.virtualenvs/py3_django_1.11/lib/python3.5/site-packages/django/views/decorators/csrf.py", line 58, in wrapped_view
    return view_func(*args, **kwargs)
  File "/home/python/.virtualenvs/py3_django_1.11/lib/python3.5/site-packages/django/views/generic/base.py", line 68, in view
    return self.dispatch(request, *args, **kwargs)
  File "/home/python/.virtualenvs/py3_django_1.11/lib/python3.5/site-packages/rest_framework/views.py", line 483, in dispatch
    response = self.handle_exception(exc)
  File "/home/python/.virtualenvs/py3_django_1.11/lib/python3.5/site-packages/rest_framework/views.py", line 443, in handle_exception
    self.raise_uncaught_exception(exc)
  File "/home/python/.virtualenvs/py3_django_1.11/lib/python3.5/site-packages/rest_framework/views.py", line 480, in dispatch
    response = handler(request, *args, **kwargs)
  File "/home/python/Desktop/meiduomall/ManyBeautifulMall/ManyBeautiful/ManyBeautifulMall/apps/oauth/views.py", line 95, in post
    serializer.is_valid()
  File "/home/python/.virtualenvs/py3_django_1.11/lib/python3.5/site-packages/rest_framework/serializers.py", line 236, in is_valid
    self._validated_data = self.run_validation(self.initial_data)
  File "/home/python/.virtualenvs/py3_django_1.11/lib/python3.5/site-packages/rest_framework/serializers.py", line 437, in run_validation
    value = self.validate(value)
  File "/home/python/Desktop/meiduomall/ManyBeautifulMall/ManyBeautiful/ManyBeautifulMall/apps/oauth/serializers.py", line 51, in validate
    openid = OAuthQQ.check_seve_user_token(access_token)
  File "/home/python/Desktop/meiduomall/ManyBeautifulMall/ManyBeautiful/ManyBeautifulMall/apps/oauth/utils.py", line 131, in check_seve_user_token
    serializer = Serializer(settings.SERCET_KEY, expires_in=constants.SAVE_QQ_USER_TOKEN_EXPIRES)
  File "/home/python/.virtualenvs/py3_django_1.11/lib/python3.5/site-packages/django/conf/__init__.py", line 57, in __getattr__
    val = getattr(self._wrapped, name)
AttributeError: 'Settings' object has no attribute 'SERCET_KEY'
ERROR 2018-10-27 11:24:25,895 basehttp 124 "POST /oauth/qq/user/ HTTP/1.1" 500 19960
ERROR 2018-10-27 11:24:47,184 utils 78 code=None msg=None
ERROR 2018-10-27 11:24:47,186 basehttp 124 "GET /oauth/qq/user/?code=D8167C39FF3E11ECE1E216B9AC01F6F9 HTTP/1.1" 503 28
INFO 2018-10-27 11:25:03,603 basehttp 124 "GET /oauth/qq/user/?code=3C41BC290F43AAD85CE85CE2C616F778 HTTP/1.1" 200 233
INFO 2018-10-27 11:25:13,462 basehttp 124 "GET /sms_code/17605272633/ HTTP/1.1" 200 16
ERROR 2018-10-27 11:25:19,221 exception 135 Internal Server Error: /oauth/qq/user/
Traceback (most recent call last):
  File "/home/python/.virtualenvs/py3_django_1.11/lib/python3.5/site-packages/django/core/handlers/exception.py", line 41, in inner
    response = get_response(request)
  File "/home/python/.virtualenvs/py3_django_1.11/lib/python3.5/site-packages/django/core/handlers/base.py", line 187, in _get_response
    response = self.process_exception_by_middleware(e, request)
  File "/home/python/.virtualenvs/py3_django_1.11/lib/python3.5/site-packages/django/core/handlers/base.py", line 185, in _get_response
    response = wrapped_callback(request, *callback_args, **callback_kwargs)
  File "/home/python/.virtualenvs/py3_django_1.11/lib/python3.5/site-packages/django/views/decorators/csrf.py", line 58, in wrapped_view
    return view_func(*args, **kwargs)
  File "/home/python/.virtualenvs/py3_django_1.11/lib/python3.5/site-packages/django/views/generic/base.py", line 68, in view
    return self.dispatch(request, *args, **kwargs)
  File "/home/python/.virtualenvs/py3_django_1.11/lib/python3.5/site-packages/rest_framework/views.py", line 483, in dispatch
    response = self.handle_exception(exc)
  File "/home/python/.virtualenvs/py3_django_1.11/lib/python3.5/site-packages/rest_framework/views.py", line 443, in handle_exception
    self.raise_uncaught_exception(exc)
  File "/home/python/.virtualenvs/py3_django_1.11/lib/python3.5/site-packages/rest_framework/views.py", line 480, in dispatch
    response = handler(request, *args, **kwargs)
  File "/home/python/Desktop/meiduomall/ManyBeautifulMall/ManyBeautiful/ManyBeautifulMall/apps/oauth/views.py", line 95, in post
    serializer.is_valid()
  File "/home/python/.virtualenvs/py3_django_1.11/lib/python3.5/site-packages/rest_framework/serializers.py", line 236, in is_valid
    self._validated_data = self.run_validation(self.initial_data)
  File "/home/python/.virtualenvs/py3_django_1.11/lib/python3.5/site-packages/rest_framework/serializers.py", line 437, in run_validation
    value = self.validate(value)
  File "/home/python/Desktop/meiduomall/ManyBeautifulMall/ManyBeautiful/ManyBeautifulMall/apps/oauth/serializers.py", line 51, in validate
    openid = OAuthQQ.check_seve_user_token(access_token)
  File "/home/python/Desktop/meiduomall/ManyBeautifulMall/ManyBeautiful/ManyBeautifulMall/apps/oauth/utils.py", line 131, in check_seve_user_token
    serializer = Serializer(settings.SERCET_KEY, expires_in=constants.SAVE_QQ_USER_TOKEN_EXPIRES)
  File "/home/python/.virtualenvs/py3_django_1.11/lib/python3.5/site-packages/django/conf/__init__.py", line 57, in __getattr__
    val = getattr(self._wrapped, name)
AttributeError: 'Settings' object has no attribute 'SERCET_KEY'
ERROR 2018-10-27 11:25:19,249 basehttp 124 "POST /oauth/qq/user/ HTTP/1.1" 500 19960
INFO 2018-10-27 11:26:08,203 basehttp 124 "GET /oauth/qq/user/?code=03FA641160D7A63F562BC8B909CCCC30 HTTP/1.1" 200 233
INFO 2018-10-27 11:26:13,888 basehttp 124 "GET /sms_code/17605272633/ HTTP/1.1" 200 16
INFO 2018-10-27 11:26:20,136 basehttp 124 "OPTIONS /oauth/qq/user/ HTTP/1.1" 200 0
ERROR 2018-10-27 11:26:20,147 exception 135 Internal Server Error: /oauth/qq/user/
Traceback (most recent call last):
  File "/home/python/.virtualenvs/py3_django_1.11/lib/python3.5/site-packages/django/core/handlers/exception.py", line 41, in inner
    response = get_response(request)
  File "/home/python/.virtualenvs/py3_django_1.11/lib/python3.5/site-packages/django/core/handlers/base.py", line 187, in _get_response
    response = self.process_exception_by_middleware(e, request)
  File "/home/python/.virtualenvs/py3_django_1.11/lib/python3.5/site-packages/django/core/handlers/base.py", line 185, in _get_response
    response = wrapped_callback(request, *callback_args, **callback_kwargs)
  File "/home/python/.virtualenvs/py3_django_1.11/lib/python3.5/site-packages/django/views/decorators/csrf.py", line 58, in wrapped_view
    return view_func(*args, **kwargs)
  File "/home/python/.virtualenvs/py3_django_1.11/lib/python3.5/site-packages/django/views/generic/base.py", line 68, in view
    return self.dispatch(request, *args, **kwargs)
  File "/home/python/.virtualenvs/py3_django_1.11/lib/python3.5/site-packages/rest_framework/views.py", line 483, in dispatch
    response = self.handle_exception(exc)
  File "/home/python/.virtualenvs/py3_django_1.11/lib/python3.5/site-packages/rest_framework/views.py", line 443, in handle_exception
    self.raise_uncaught_exception(exc)
  File "/home/python/.virtualenvs/py3_django_1.11/lib/python3.5/site-packages/rest_framework/views.py", line 480, in dispatch
    response = handler(request, *args, **kwargs)
  File "/home/python/Desktop/meiduomall/ManyBeautifulMall/ManyBeautiful/ManyBeautifulMall/apps/oauth/views.py", line 95, in post
    serializer.is_valid()
  File "/home/python/.virtualenvs/py3_django_1.11/lib/python3.5/site-packages/rest_framework/serializers.py", line 236, in is_valid
    self._validated_data = self.run_validation(self.initial_data)
  File "/home/python/.virtualenvs/py3_django_1.11/lib/python3.5/site-packages/rest_framework/serializers.py", line 437, in run_validation
    value = self.validate(value)
  File "/home/python/Desktop/meiduomall/ManyBeautifulMall/ManyBeautiful/ManyBeautifulMall/apps/oauth/serializers.py", line 51, in validate
    openid = OAuthQQ.check_seve_user_token(access_token)
  File "/home/python/Desktop/meiduomall/ManyBeautifulMall/ManyBeautiful/ManyBeautifulMall/apps/oauth/utils.py", line 131, in check_seve_user_token
    serializer = Serializer(settings.SERCET_KEY, expires_in=constants.SAVE_QQ_USER_TOKEN_EXPIRES)
  File "/home/python/.virtualenvs/py3_django_1.11/lib/python3.5/site-packages/django/conf/__init__.py", line 57, in __getattr__
    val = getattr(self._wrapped, name)
AttributeError: 'Settings' object has no attribute 'SERCET_KEY'
ERROR 2018-10-27 11:26:20,213 basehttp 124 "POST /oauth/qq/user/ HTTP/1.1" 500 19960
ERROR 2018-10-27 11:27:30,233 utils 102 code=None msg=None
ERROR 2018-10-27 11:27:30,239 basehttp 124 "GET /oauth/qq/user/?code=D9BD77FF087E5007E4A0413F5024DA31 HTTP/1.1" 503 28
ERROR 2018-10-27 11:27:35,716 utils 78 code=None msg=None
ERROR 2018-10-27 11:27:35,721 basehttp 124 "GET /oauth/qq/user/?code=D9BD77FF087E5007E4A0413F5024DA31 HTTP/1.1" 503 28
ERROR 2018-10-27 11:27:51,057 utils 102 code=None msg=None
ERROR 2018-10-27 11:27:51,063 basehttp 124 "GET /oauth/qq/user/?code=2E383DCF2E97A61B9FD69F1CB152CB92 HTTP/1.1" 503 28
INFO 2018-10-27 11:28:37,833 basehttp 124 "GET /oauth/qq/user/?code=6A63EA16BC70E3ABC98EFE63E8ABECEB HTTP/1.1" 200 233
ERROR 2018-10-27 11:29:14,836 utils 102 code=None msg=None
ERROR 2018-10-27 11:29:14,842 basehttp 124 "GET /oauth/qq/user/?code=B15E398F62ADE9BA0DF7F4705AA14701 HTTP/1.1" 503 28
ERROR 2018-10-27 11:29:54,122 utils 103 code=None msg=None
ERROR 2018-10-27 11:29:54,196 basehttp 124 "GET /oauth/qq/user/?code=12846107731147E97E9F552934FB4B96 HTTP/1.1" 503 28
INFO 2018-10-27 11:30:24,962 basehttp 124 "GET /oauth/qq/user/?code=57EBB66190D7FE46249CA8741C3A99F2 HTTP/1.1" 200 233
INFO 2018-10-27 11:32:09,546 basehttp 124 "GET /sms_code/17605272633/ HTTP/1.1" 200 16
ERROR 2018-10-27 11:32:16,459 exception 135 Internal Server Error: /oauth/qq/user/
Traceback (most recent call last):
  File "/home/python/.virtualenvs/py3_django_1.11/lib/python3.5/site-packages/django/core/handlers/exception.py", line 41, in inner
    response = get_response(request)
  File "/home/python/.virtualenvs/py3_django_1.11/lib/python3.5/site-packages/django/core/handlers/base.py", line 187, in _get_response
    response = self.process_exception_by_middleware(e, request)
  File "/home/python/.virtualenvs/py3_django_1.11/lib/python3.5/site-packages/django/core/handlers/base.py", line 185, in _get_response
    response = wrapped_callback(request, *callback_args, **callback_kwargs)
  File "/home/python/.virtualenvs/py3_django_1.11/lib/python3.5/site-packages/django/views/decorators/csrf.py", line 58, in wrapped_view
    return view_func(*args, **kwargs)
  File "/home/python/.virtualenvs/py3_django_1.11/lib/python3.5/site-packages/django/views/generic/base.py", line 68, in view
    return self.dispatch(request, *args, **kwargs)
  File "/home/python/.virtualenvs/py3_django_1.11/lib/python3.5/site-packages/rest_framework/views.py", line 483, in dispatch
    response = self.handle_exception(exc)
  File "/home/python/.virtualenvs/py3_django_1.11/lib/python3.5/site-packages/rest_framework/views.py", line 443, in handle_exception
    self.raise_uncaught_exception(exc)
  File "/home/python/.virtualenvs/py3_django_1.11/lib/python3.5/site-packages/rest_framework/views.py", line 480, in dispatch
    response = handler(request, *args, **kwargs)
  File "/home/python/Desktop/meiduomall/ManyBeautifulMall/ManyBeautiful/ManyBeautifulMall/apps/oauth/views.py", line 95, in post
    serializer.is_valid()
  File "/home/python/.virtualenvs/py3_django_1.11/lib/python3.5/site-packages/rest_framework/serializers.py", line 236, in is_valid
    self._validated_data = self.run_validation(self.initial_data)
  File "/home/python/.virtualenvs/py3_django_1.11/lib/python3.5/site-packages/rest_framework/serializers.py", line 437, in run_validation
    value = self.validate(value)
  File "/home/python/Desktop/meiduomall/ManyBeautifulMall/ManyBeautiful/ManyBeautifulMall/apps/oauth/serializers.py", line 51, in validate
    openid = OAuthQQ.check_seve_user_token(access_token)
  File "/home/python/Desktop/meiduomall/ManyBeautifulMall/ManyBeautiful/ManyBeautifulMall/apps/oauth/utils.py", line 132, in check_seve_user_token
    serializer = Serializer(settings.SERCET_KEY, expires_in=constants.SAVE_QQ_USER_TOKEN_EXPIRES)
  File "/home/python/.virtualenvs/py3_django_1.11/lib/python3.5/site-packages/django/conf/__init__.py", line 57, in __getattr__
    val = getattr(self._wrapped, name)
AttributeError: 'Settings' object has no attribute 'SERCET_KEY'
ERROR 2018-10-27 11:32:16,529 basehttp 124 "POST /oauth/qq/user/ HTTP/1.1" 500 19960
INFO 2018-10-27 11:33:24,887 basehttp 124 "GET /oauth/qq/user/?code=1C84814824D0AA40141C905673FD2769 HTTP/1.1" 200 233
INFO 2018-10-27 11:33:33,388 basehttp 124 "GET /sms_code/17605272633/ HTTP/1.1" 200 16
ERROR 2018-10-27 11:33:39,821 exception 135 Internal Server Error: /oauth/qq/user/
Traceback (most recent call last):
  File "/home/python/.virtualenvs/py3_django_1.11/lib/python3.5/site-packages/django/core/handlers/exception.py", line 41, in inner
    response = get_response(request)
  File "/home/python/.virtualenvs/py3_django_1.11/lib/python3.5/site-packages/django/core/handlers/base.py", line 187, in _get_response
    response = self.process_exception_by_middleware(e, request)
  File "/home/python/.virtualenvs/py3_django_1.11/lib/python3.5/site-packages/django/core/handlers/base.py", line 185, in _get_response
    response = wrapped_callback(request, *callback_args, **callback_kwargs)
  File "/home/python/.virtualenvs/py3_django_1.11/lib/python3.5/site-packages/django/views/decorators/csrf.py", line 58, in wrapped_view
    return view_func(*args, **kwargs)
  File "/home/python/.virtualenvs/py3_django_1.11/lib/python3.5/site-packages/django/views/generic/base.py", line 68, in view
    return self.dispatch(request, *args, **kwargs)
  File "/home/python/.virtualenvs/py3_django_1.11/lib/python3.5/site-packages/rest_framework/views.py", line 483, in dispatch
    response = self.handle_exception(exc)
  File "/home/python/.virtualenvs/py3_django_1.11/lib/python3.5/site-packages/rest_framework/views.py", line 443, in handle_exception
    self.raise_uncaught_exception(exc)
  File "/home/python/.virtualenvs/py3_django_1.11/lib/python3.5/site-packages/rest_framework/views.py", line 480, in dispatch
    response = handler(request, *args, **kwargs)
  File "/home/python/Desktop/meiduomall/ManyBeautifulMall/ManyBeautiful/ManyBeautifulMall/apps/oauth/views.py", line 95, in post
    serializer.is_valid()
  File "/home/python/.virtualenvs/py3_django_1.11/lib/python3.5/site-packages/rest_framework/serializers.py", line 236, in is_valid
    self._validated_data = self.run_validation(self.initial_data)
  File "/home/python/.virtualenvs/py3_django_1.11/lib/python3.5/site-packages/rest_framework/serializers.py", line 437, in run_validation
    value = self.validate(value)
  File "/home/python/Desktop/meiduomall/ManyBeautifulMall/ManyBeautiful/ManyBeautifulMall/apps/oauth/serializers.py", line 51, in validate
    openid = OAuthQQ.check_seve_user_token(access_token)
  File "/home/python/Desktop/meiduomall/ManyBeautifulMall/ManyBeautiful/ManyBeautifulMall/apps/oauth/utils.py", line 132, in check_seve_user_token
    serializer = Serializer(settings.SERCET_KEY, expires_in=constants.SAVE_QQ_USER_TOKEN_EXPIRES)
  File "/home/python/.virtualenvs/py3_django_1.11/lib/python3.5/site-packages/django/conf/__init__.py", line 57, in __getattr__
    val = getattr(self._wrapped, name)
AttributeError: 'Settings' object has no attribute 'SERCET_KEY'
ERROR 2018-10-27 11:33:39,926 basehttp 124 "POST /oauth/qq/user/ HTTP/1.1" 500 19960
INFO 2018-10-27 11:34:13,872 basehttp 124 "GET /oauth/qq/user/?code=E02CC589B4EE9F5F2FD35EEE16FBA158 HTTP/1.1" 200 233
WARNING 2018-10-27 11:34:25,389 basehttp 124 "GET /sms_code/17605272633/ HTTP/1.1" 400 28
WARNING 2018-10-27 11:34:29,789 basehttp 124 "GET /sms_code/17605272633/ HTTP/1.1" 400 28
WARNING 2018-10-27 11:34:31,238 basehttp 124 "GET /sms_code/17605272633/ HTTP/1.1" 400 28
WARNING 2018-10-27 11:34:31,643 basehttp 124 "GET /sms_code/17605272633/ HTTP/1.1" 400 28
WARNING 2018-10-27 11:34:31,922 basehttp 124 "GET /sms_code/17605272633/ HTTP/1.1" 400 28
WARNING 2018-10-27 11:34:32,090 basehttp 124 "GET /sms_code/17605272633/ HTTP/1.1" 400 28
WARNING 2018-10-27 11:34:32,259 basehttp 124 "GET /sms_code/17605272633/ HTTP/1.1" 400 28
WARNING 2018-10-27 11:34:32,410 basehttp 124 "GET /sms_code/17605272633/ HTTP/1.1" 400 28
WARNING 2018-10-27 11:34:32,577 basehttp 124 "GET /sms_code/17605272633/ HTTP/1.1" 400 28
WARNING 2018-10-27 11:34:32,731 basehttp 124 "GET /sms_code/17605272633/ HTTP/1.1" 400 28
WARNING 2018-10-27 11:34:32,899 basehttp 124 "GET /sms_code/17605272633/ HTTP/1.1" 400 28
WARNING 2018-10-27 11:34:33,061 basehttp 124 "GET /sms_code/17605272633/ HTTP/1.1" 400 28
WARNING 2018-10-27 11:34:33,250 basehttp 124 "GET /sms_code/17605272633/ HTTP/1.1" 400 28
INFO 2018-10-27 11:34:33,492 basehttp 124 "GET /sms_code/17605272633/ HTTP/1.1" 200 16
ERROR 2018-10-27 11:34:40,936 exception 135 Internal Server Error: /oauth/qq/user/
Traceback (most recent call last):
  File "/home/python/.virtualenvs/py3_django_1.11/lib/python3.5/site-packages/django/core/handlers/exception.py", line 41, in inner
    response = get_response(request)
  File "/home/python/.virtualenvs/py3_django_1.11/lib/python3.5/site-packages/django/core/handlers/base.py", line 187, in _get_response
    response = self.process_exception_by_middleware(e, request)
  File "/home/python/.virtualenvs/py3_django_1.11/lib/python3.5/site-packages/django/core/handlers/base.py", line 185, in _get_response
    response = wrapped_callback(request, *callback_args, **callback_kwargs)
  File "/home/python/.virtualenvs/py3_django_1.11/lib/python3.5/site-packages/django/views/decorators/csrf.py", line 58, in wrapped_view
    return view_func(*args, **kwargs)
  File "/home/python/.virtualenvs/py3_django_1.11/lib/python3.5/site-packages/django/views/generic/base.py", line 68, in view
    return self.dispatch(request, *args, **kwargs)
  File "/home/python/.virtualenvs/py3_django_1.11/lib/python3.5/site-packages/rest_framework/views.py", line 483, in dispatch
    response = self.handle_exception(exc)
  File "/home/python/.virtualenvs/py3_django_1.11/lib/python3.5/site-packages/rest_framework/views.py", line 443, in handle_exception
    self.raise_uncaught_exception(exc)
  File "/home/python/.virtualenvs/py3_django_1.11/lib/python3.5/site-packages/rest_framework/views.py", line 480, in dispatch
    response = handler(request, *args, **kwargs)
  File "/home/python/Desktop/meiduomall/ManyBeautifulMall/ManyBeautiful/ManyBeautifulMall/apps/oauth/views.py", line 95, in post
    serializer.is_valid()
  File "/home/python/.virtualenvs/py3_django_1.11/lib/python3.5/site-packages/rest_framework/serializers.py", line 236, in is_valid
    self._validated_data = self.run_validation(self.initial_data)
  File "/home/python/.virtualenvs/py3_django_1.11/lib/python3.5/site-packages/rest_framework/serializers.py", line 437, in run_validation
    value = self.validate(value)
  File "/home/python/Desktop/meiduomall/ManyBeautifulMall/ManyBeautiful/ManyBeautifulMall/apps/oauth/serializers.py", line 52, in validate
    openid = OAuthQQ.check_seve_user_token(access_token)
  File "/home/python/Desktop/meiduomall/ManyBeautifulMall/ManyBeautiful/ManyBeautifulMall/apps/oauth/utils.py", line 132, in check_seve_user_token
    serializer = Serializer(settings.SERCET_KEY, expires_in=constants.SAVE_QQ_USER_TOKEN_EXPIRES)
  File "/home/python/.virtualenvs/py3_django_1.11/lib/python3.5/site-packages/django/conf/__init__.py", line 57, in __getattr__
    val = getattr(self._wrapped, name)
AttributeError: 'Settings' object has no attribute 'SERCET_KEY'
ERROR 2018-10-27 11:34:41,005 basehttp 124 "POST /oauth/qq/user/ HTTP/1.1" 500 19960
INFO 2018-10-27 11:35:29,739 basehttp 124 "GET /oauth/qq/user/?code=7DD2E070C3D014C0B84B695A0ED043EA HTTP/1.1" 200 233
INFO 2018-10-27 11:35:37,819 basehttp 124 "GET /sms_code/17605272633/ HTTP/1.1" 200 16
ERROR 2018-10-27 11:35:43,449 exception 135 Internal Server Error: /oauth/qq/user/
Traceback (most recent call last):
  File "/home/python/.virtualenvs/py3_django_1.11/lib/python3.5/site-packages/django/core/handlers/exception.py", line 41, in inner
    response = get_response(request)
  File "/home/python/.virtualenvs/py3_django_1.11/lib/python3.5/site-packages/django/core/handlers/base.py", line 187, in _get_response
    response = self.process_exception_by_middleware(e, request)
  File "/home/python/.virtualenvs/py3_django_1.11/lib/python3.5/site-packages/django/core/handlers/base.py", line 185, in _get_response
    response = wrapped_callback(request, *callback_args, **callback_kwargs)
  File "/home/python/.virtualenvs/py3_django_1.11/lib/python3.5/site-packages/django/views/decorators/csrf.py", line 58, in wrapped_view
    return view_func(*args, **kwargs)
  File "/home/python/.virtualenvs/py3_django_1.11/lib/python3.5/site-packages/django/views/generic/base.py", line 68, in view
    return self.dispatch(request, *args, **kwargs)
  File "/home/python/.virtualenvs/py3_django_1.11/lib/python3.5/site-packages/rest_framework/views.py", line 483, in dispatch
    response = self.handle_exception(exc)
  File "/home/python/.virtualenvs/py3_django_1.11/lib/python3.5/site-packages/rest_framework/views.py", line 443, in handle_exception
    self.raise_uncaught_exception(exc)
  File "/home/python/.virtualenvs/py3_django_1.11/lib/python3.5/site-packages/rest_framework/views.py", line 480, in dispatch
    response = handler(request, *args, **kwargs)
  File "/home/python/Desktop/meiduomall/ManyBeautifulMall/ManyBeautiful/ManyBeautifulMall/apps/oauth/views.py", line 95, in post
    serializer.is_valid()
  File "/home/python/.virtualenvs/py3_django_1.11/lib/python3.5/site-packages/rest_framework/serializers.py", line 236, in is_valid
    self._validated_data = self.run_validation(self.initial_data)
  File "/home/python/.virtualenvs/py3_django_1.11/lib/python3.5/site-packages/rest_framework/serializers.py", line 437, in run_validation
    value = self.validate(value)
  File "/home/python/Desktop/meiduomall/ManyBeautifulMall/ManyBeautiful/ManyBeautifulMall/apps/oauth/serializers.py", line 52, in validate
    openid = OAuthQQ.check_seve_user_token(access_token)
  File "/home/python/Desktop/meiduomall/ManyBeautifulMall/ManyBeautiful/ManyBeautifulMall/apps/oauth/utils.py", line 132, in check_seve_user_token
    serializer = Serializer(settings.SERCET_KEY, expires_in=constants.SAVE_QQ_USER_TOKEN_EXPIRES)
  File "/home/python/.virtualenvs/py3_django_1.11/lib/python3.5/site-packages/django/conf/__init__.py", line 57, in __getattr__
    val = getattr(self._wrapped, name)
AttributeError: 'Settings' object has no attribute 'SERCET_KEY'
ERROR 2018-10-27 11:35:43,541 basehttp 124 "POST /oauth/qq/user/ HTTP/1.1" 500 19960
INFO 2018-10-27 11:36:17,566 basehttp 124 "GET /oauth/qq/user/?code=F1D6279096C00B696A1C4D5D025CCFB2 HTTP/1.1" 200 233
WARNING 2018-10-27 11:36:27,518 basehttp 124 "GET /sms_code/17605272633/ HTTP/1.1" 400 28
WARNING 2018-10-27 11:36:30,545 basehttp 124 "GET /sms_code/17605272633/ HTTP/1.1" 400 28
WARNING 2018-10-27 11:36:31,655 basehttp 124 "GET /sms_code/17605272633/ HTTP/1.1" 400 28
WARNING 2018-10-27 11:36:36,207 basehttp 124 "GET /sms_code/17605272633/ HTTP/1.1" 400 28
WARNING 2018-10-27 11:36:36,985 basehttp 124 "GET /sms_code/17605272633/ HTTP/1.1" 400 28
WARNING 2018-10-27 11:36:37,519 basehttp 124 "GET /sms_code/17605272633/ HTTP/1.1" 400 28
INFO 2018-10-27 11:36:38,048 basehttp 124 "GET /sms_code/17605272633/ HTTP/1.1" 200 16
INFO 2018-10-27 11:36:45,197 basehttp 124 "OPTIONS /oauth/qq/user/ HTTP/1.1" 200 0
ERROR 2018-10-27 11:36:45,213 exception 135 Internal Server Error: /oauth/qq/user/
Traceback (most recent call last):
  File "/home/python/.virtualenvs/py3_django_1.11/lib/python3.5/site-packages/django/core/handlers/exception.py", line 41, in inner
    response = get_response(request)
  File "/home/python/.virtualenvs/py3_django_1.11/lib/python3.5/site-packages/django/core/handlers/base.py", line 187, in _get_response
    response = self.process_exception_by_middleware(e, request)
  File "/home/python/.virtualenvs/py3_django_1.11/lib/python3.5/site-packages/django/core/handlers/base.py", line 185, in _get_response
    response = wrapped_callback(request, *callback_args, **callback_kwargs)
  File "/home/python/.virtualenvs/py3_django_1.11/lib/python3.5/site-packages/django/views/decorators/csrf.py", line 58, in wrapped_view
    return view_func(*args, **kwargs)
  File "/home/python/.virtualenvs/py3_django_1.11/lib/python3.5/site-packages/django/views/generic/base.py", line 68, in view
    return self.dispatch(request, *args, **kwargs)
  File "/home/python/.virtualenvs/py3_django_1.11/lib/python3.5/site-packages/rest_framework/views.py", line 483, in dispatch
    response = self.handle_exception(exc)
  File "/home/python/.virtualenvs/py3_django_1.11/lib/python3.5/site-packages/rest_framework/views.py", line 443, in handle_exception
    self.raise_uncaught_exception(exc)
  File "/home/python/.virtualenvs/py3_django_1.11/lib/python3.5/site-packages/rest_framework/views.py", line 480, in dispatch
    response = handler(request, *args, **kwargs)
  File "/home/python/Desktop/meiduomall/ManyBeautifulMall/ManyBeautiful/ManyBeautifulMall/apps/oauth/views.py", line 95, in post
    serializer.is_valid()
  File "/home/python/.virtualenvs/py3_django_1.11/lib/python3.5/site-packages/rest_framework/serializers.py", line 236, in is_valid
    self._validated_data = self.run_validation(self.initial_data)
  File "/home/python/.virtualenvs/py3_django_1.11/lib/python3.5/site-packages/rest_framework/serializers.py", line 437, in run_validation
    value = self.validate(value)
  File "/home/python/Desktop/meiduomall/ManyBeautifulMall/ManyBeautiful/ManyBeautifulMall/apps/oauth/serializers.py", line 53, in validate
    openid = OAuthQQ.check_seve_user_token(access_token)
  File "/home/python/Desktop/meiduomall/ManyBeautifulMall/ManyBeautiful/ManyBeautifulMall/apps/oauth/utils.py", line 132, in check_seve_user_token
    serializer = Serializer(settings.SERCET_KEY, expires_in=constants.SAVE_QQ_USER_TOKEN_EXPIRES)
  File "/home/python/.virtualenvs/py3_django_1.11/lib/python3.5/site-packages/django/conf/__init__.py", line 57, in __getattr__
    val = getattr(self._wrapped, name)
AttributeError: 'Settings' object has no attribute 'SERCET_KEY'
ERROR 2018-10-27 11:36:45,273 basehttp 124 "POST /oauth/qq/user/ HTTP/1.1" 500 19960
INFO 2018-10-27 11:37:15,784 basehttp 124 "GET /oauth/qq/user/?code=B083930225EDDC4B04BBE1131C51B3D6 HTTP/1.1" 200 233
INFO 2018-10-27 11:40:41,212 basehttp 124 "GET /sms_code/17605272633/ HTTP/1.1" 200 16
ERROR 2018-10-27 11:40:50,308 exception 135 Internal Server Error: /oauth/qq/user/
Traceback (most recent call last):
  File "/home/python/.virtualenvs/py3_django_1.11/lib/python3.5/site-packages/django/core/handlers/exception.py", line 41, in inner
    response = get_response(request)
  File "/home/python/.virtualenvs/py3_django_1.11/lib/python3.5/site-packages/django/core/handlers/base.py", line 187, in _get_response
    response = self.process_exception_by_middleware(e, request)
  File "/home/python/.virtualenvs/py3_django_1.11/lib/python3.5/site-packages/django/core/handlers/base.py", line 185, in _get_response
    response = wrapped_callback(request, *callback_args, **callback_kwargs)
  File "/home/python/.virtualenvs/py3_django_1.11/lib/python3.5/site-packages/django/views/decorators/csrf.py", line 58, in wrapped_view
    return view_func(*args, **kwargs)
  File "/home/python/.virtualenvs/py3_django_1.11/lib/python3.5/site-packages/django/views/generic/base.py", line 68, in view
    return self.dispatch(request, *args, **kwargs)
  File "/home/python/.virtualenvs/py3_django_1.11/lib/python3.5/site-packages/rest_framework/views.py", line 483, in dispatch
    response = self.handle_exception(exc)
  File "/home/python/.virtualenvs/py3_django_1.11/lib/python3.5/site-packages/rest_framework/views.py", line 443, in handle_exception
    self.raise_uncaught_exception(exc)
  File "/home/python/.virtualenvs/py3_django_1.11/lib/python3.5/site-packages/rest_framework/views.py", line 480, in dispatch
    response = handler(request, *args, **kwargs)
  File "/home/python/Desktop/meiduomall/ManyBeautifulMall/ManyBeautiful/ManyBeautifulMall/apps/oauth/views.py", line 95, in post
    serializer.is_valid()
  File "/home/python/.virtualenvs/py3_django_1.11/lib/python3.5/site-packages/rest_framework/serializers.py", line 236, in is_valid
    self._validated_data = self.run_validation(self.initial_data)
  File "/home/python/.virtualenvs/py3_django_1.11/lib/python3.5/site-packages/rest_framework/serializers.py", line 437, in run_validation
    value = self.validate(value)
  File "/home/python/Desktop/meiduomall/ManyBeautifulMall/ManyBeautiful/ManyBeautifulMall/apps/oauth/serializers.py", line 52, in validate
    openid = OAuthQQ.check_seve_user_token(access_token)
  File "/home/python/Desktop/meiduomall/ManyBeautifulMall/ManyBeautiful/ManyBeautifulMall/apps/oauth/utils.py", line 132, in check_seve_user_token
    serializer = Serializer(settings.SERCET_KEY, expires_in=constants.SAVE_QQ_USER_TOKEN_EXPIRES)
  File "/home/python/.virtualenvs/py3_django_1.11/lib/python3.5/site-packages/django/conf/__init__.py", line 57, in __getattr__
    val = getattr(self._wrapped, name)
AttributeError: 'Settings' object has no attribute 'SERCET_KEY'
ERROR 2018-10-27 11:40:50,385 basehttp 124 "POST /oauth/qq/user/ HTTP/1.1" 500 19960
INFO 2018-10-27 11:42:13,464 basehttp 124 "GET /oauth/qq/user/?code=2DF0EB7179FE78051FA1E323B2F566D7 HTTP/1.1" 200 233
INFO 2018-10-27 11:42:19,624 basehttp 124 "GET /sms_code/17605272633/ HTTP/1.1" 200 16
ERROR 2018-10-27 11:42:31,041 exception 135 Internal Server Error: /oauth/qq/user/
Traceback (most recent call last):
  File "/home/python/.virtualenvs/py3_django_1.11/lib/python3.5/site-packages/django/core/handlers/exception.py", line 41, in inner
    response = get_response(request)
  File "/home/python/.virtualenvs/py3_django_1.11/lib/python3.5/site-packages/django/core/handlers/base.py", line 187, in _get_response
    response = self.process_exception_by_middleware(e, request)
  File "/home/python/.virtualenvs/py3_django_1.11/lib/python3.5/site-packages/django/core/handlers/base.py", line 185, in _get_response
    response = wrapped_callback(request, *callback_args, **callback_kwargs)
  File "/home/python/.virtualenvs/py3_django_1.11/lib/python3.5/site-packages/django/views/decorators/csrf.py", line 58, in wrapped_view
    return view_func(*args, **kwargs)
  File "/home/python/.virtualenvs/py3_django_1.11/lib/python3.5/site-packages/django/views/generic/base.py", line 68, in view
    return self.dispatch(request, *args, **kwargs)
  File "/home/python/.virtualenvs/py3_django_1.11/lib/python3.5/site-packages/rest_framework/views.py", line 483, in dispatch
    response = self.handle_exception(exc)
  File "/home/python/.virtualenvs/py3_django_1.11/lib/python3.5/site-packages/rest_framework/views.py", line 443, in handle_exception
    self.raise_uncaught_exception(exc)
  File "/home/python/.virtualenvs/py3_django_1.11/lib/python3.5/site-packages/rest_framework/views.py", line 480, in dispatch
    response = handler(request, *args, **kwargs)
  File "/home/python/Desktop/meiduomall/ManyBeautifulMall/ManyBeautiful/ManyBeautifulMall/apps/oauth/views.py", line 97, in post
    user = serializer.save()
  File "/home/python/.virtualenvs/py3_django_1.11/lib/python3.5/site-packages/rest_framework/serializers.py", line 216, in save
    '`create()` did not return an object instance.'
AssertionError: `create()` did not return an object instance.
ERROR 2018-10-27 11:42:31,089 basehttp 124 "POST /oauth/qq/user/ HTTP/1.1" 500 19162
INFO 2018-10-27 11:43:53,098 basehttp 124 "GET /oauth/qq/user/?code=C381820275D22D54727D5F19998866EE HTTP/1.1" 200 211
INFO 2018-10-27 11:45:06,107 basehttp 124 "GET /oauth/qq/authorization/?next=/ HTTP/1.1" 200 175
INFO 2018-10-27 11:45:15,877 basehttp 124 "GET /oauth/qq/user/?code=DF8D41017483ACE3E4F97CDAF77F5AC4 HTTP/1.1" 200 233
INFO 2018-10-27 11:45:21,773 basehttp 124 "GET /sms_code/17605272633/ HTTP/1.1" 200 16
INFO 2018-10-27 11:45:30,679 basehttp 124 "POST /oauth/qq/user/ HTTP/1.1" 200 211
